Workbook

Sheet INSTRUCCIONES
A1: CARGA EN GRAPHPAD PRISM – SLR (DI y tasa de exploración)
A3: 1. New Table & Graph → Grouped → 'Enter 10 replicate values in side-by-side subcolumns'.
A4: 2. Grupos de columnas: Control, Sacarosa, Stevia. Filas: Juvenil, Adulto.
A5: 3. Copiar el bloque B6:AE7 de la hoja correspondiente y pegarlo en Prism. Celdas vacías = n<10.
A6: 4. Analyze → Two-way ANOVA. Factores: filas = Edad, columnas = Tratamiento. Multiple comparisons: Tukey.
A7: 5. Una hoja por análisis: DI d-SLR, DI s-SLR, Tasa d-SLR, Tasa s-SLR (la configuración NO se mezcla).
A8: 6. Complemento: t de una muestra contra 0 (DI) / 0,5 (tasa) por celda, para saber si cada grupo discrimina.
A10: CORRECCIÓN APLICADA
A11: • Test adulto de mayo (250509): se corrigió la asignación novedoso/familiar, que estaba invertida en la carga original (Zona 1 era familiar, no novedoso). Todos los DI de esa hoja cambiaron de signo. Afecta al control y a la sacarosa adultos de mayo; no toca ninguna otra cohorte.
A13: ADVERTENCIAS
A14: • DI y tasa son el mismo dato reescalado (DI = 2·tasa − 1): los p del ANOVA serán idénticos. Se reporta una vez.
A15: • Controles de octubre (juv) y diciembre (adu) hicieron ambas configuraciones (diseño cruzado): cada uno aparece una vez en d-SLR y una vez en s-SLR; dentro de cada ANOVA no hay repetidos.
... A17: • Falta confirmar identidad de animales 1-10 del test adulto 2026 con ranas (asumido 1-5 sac, 6-10 stevia).

Sheet  D-SLR
A1: tasa – D-SLR (EQUILTERO)
A2: Azar = 0,5. Filas = Edad; grupos de columnas = Tratamiento; subcolumnas = animales.
B4: Control | L4: Sacarosa | V4: Stevia
B5: 1 | C5: 2 | D5: 3 | E5: 4 | F5: 5 | G5: 6 | H5: 7 | I5: 8 | J5: 9 | K5: 10 | L5: 1 | M5: 2 | N5: 3 | O5: 4 | P5: 5 | Q5: 6 | R5: 7 | S5: 8 | T5: 9 | U5: 10 | V5: 1 | W5: 2 | X5: 3 | Y5: 4 | Z5: 5 | AA5: 6 | AB5: 7 | AC5: 8 | AD5: 9 | AE5: 10
A6: Juvenil | B6: 0.702 | C6: 0.553 | D6: 0.527 | E6: 0.572 | F6: 0.623 | G6: 0.766 | H6: 0.584 | I6: 0.612 | J6: 0.65 | L6: 0.423 | M6: 0.557 | N6: 0.375 | O6: 0.542 | P6: 0.347 | Q6: 0.456 | R6: 0.519 | S6: 0.472 | T6: 0.441 | V6: 0.531 | W6: 0.529 | X6: 0.427 | Y6: 0.632 | Z6: 0.472 | AA6: 0.731 | AB6: 0.559 | AC6: 0.828 | AD6: 0.843 | AE6: 0.401
A7: Adulto | B7: 0.682 | C7: 0.506 | D7: 0.746 | E7: 0.485 | F7: 0.578 | G7: 0.642 | H7: 0.538 | I7: 0.578 | J7: 0.638 | K7: 0.696 | L7: 0.558 | M7: 0.566 | N7: 0.437 | O7: 0.511 | P7: 0.575 | Q7: 0.58 | R7: 0.341 | S7: 0.667 | T7: 0.77 | U7: 0.54 | V7: 0.498 | W7: 0.693 | X7: 0.563 | Y7: 0.577 | Z7: 0.502 | AA7: 0.336 | AB7: 0.766 | AC7: 0.634 | AD7: 0.432 | AE7: 0.529
A9: Bloque a copiar en Prism: B6:AE7 (solo valores). | H9: ctrol | I9: sacarosa | J9: stevia
G10: juv | H10: =(B6+C6+D6+E6+F6+G6+H6+I6+J6)/9 | I10: =AVERAGE(L6:T6) | J10: =AVERAGE(V6:AE6)
G11: adulto | H11: =AVERAGE(B7:K7) | I11: =AVERAGE(L7:U7) | J11: =AVERAGE(V7:AE7)

Sheet D SLR ANOVA TASA EXP
A2: Table Analyzed | B2: D SLR TASA EXPLORACION
A4: Two-way ANOVA | B4: Ordinary
A5: Alpha | B5: 0.05
A7: Source of Variation | B7: % of total variation | C7: P value | D7: P value summary | E7: Significant?
A8: Interaction | B8: 6.286 | C8: 0.1401 | D8: ns | E8: No
A9: Row Factor | B9: 0.3366 | C9: 0.642 | D9: ns | E9: No
A10: Column Factor | B10: 14.1 | C10: 0.0147 | D10: * | E10: Yes
A12: ANOVA table | B12: SS (Type III) | C12: DF | D12: MS | E12: F (DFn, DFd) | F12: P value
A13: Interaction | B13: 0.05043 | C13: 2 | D13: 0.02521 | E13: F (2, 52) = 2.042 | F13: P=0.1401
A14: Row Factor | B14: 0.0027 | C14: 1 | D14: 0.0027 | E14: F (1, 52) = 0.2187 | F14: P=0.6420
A15: Column Factor | B15: 0.1131 | C15: 2 | D15: 0.05655 | E15: F (2, 52) = 4.580 | F15: P=0.0147
A16: Residual | B16: 0.6421 | C16: 52 | D16: 0.01235
A17: Total | B17: 0.8022 | C17: 57
A19: Difference between row means
A20: Predicted (LS) mean of Juvenil | B20: 0.5585
A21: Predicted (LS) mean of Adulto | B21: 0.5721
A22: Difference between predicted means | B22: -0.01366
A23: SE of difference | B23: 0.02922
A24: 95% CI of difference | B24: -0.07229 to 0.04497
A26: Data summary
A27: Number of columns (Column Factor) | B27: 3
A28: Number of rows (Row Factor) | B28: 2
A29: Number of values | B29: 58

Sheet MULTIPLE D SLR TASA EXP
A2: Compare cell means with others in its row and its column
A4: Number of families | B4: 5
A5: Number of comparisons per row family | B5: 3
A6: Number of comparisons per column family | B6: 1
A7: Alpha | B7: 0.05
A9: Tukey's multiple comparisons test | B9: Predicted (LS) Mean diff. | C9: 95.00% CI of diff. | D9: Below threshold? | E9: Summary | F9: Adjusted P Value
A11: Adulto
A12: CONTROL vs. SACAROSA | B12: 0.0544 | C12: -0.06550 to 0.1743 | D12: No | E12: ns | F12: 0.5216
A13: CONTROL vs. STEVIA | B13: 0.0559 | C13: -0.06400 to 0.1758 | D13: No | E13: ns | F13: 0.5033
A14: SACAROSA vs. STEVIA | B14: 0.0015 | C14: -0.1184 to 0.1214 | D14: No | E14: ns | F14: 0.9995
A16: Juvenil
A17: CONTROL vs. SACAROSA | B17: 0.1619 | C17: 0.03551 to 0.2883 | D17: Yes | E17: ** | F17: 0.0089
A18: CONTROL vs. STEVIA | B18: 0.0257 | C18: -0.09748 to 0.1489 | D18: No | E18: ns | F18: 0.87
A19: SACAROSA vs. STEVIA | B19: -0.1362 | C19: -0.2594 to -0.01301 | D19: Yes | E19: * | F19: 0.027
A21: CONTROL
A22: Juvenil vs. Adulto | B22: 0.0121 | C22: -0.09035 to 0.1146 | D22: No | E22: ns | F22: 0.8136
A24: SACAROSA
A25: Juvenil vs. Adulto | B25: -0.09539 | C25: -0.1978 to 0.007065 | D25: No | E25: ns | F25: 0.0674
A27: STEVIA
A28: Juvenil vs. Adulto | B28: 0.0423 | C28: -0.05742 to 0.1420 | D28: No | E28: ns | F28: 0.3986
A31: Test details | B31: Predicted (LS) Mean 1 | C31: Predicted (LS) Mean 2 | D31: Predicted (LS) Mean diff. | E31: SE of diff. | F31: N1 | G31: N2 | H31: q | I31: DF
A33: Adulto
A34: CONTROL vs. SACAROSA | B34: 0.6089 | C34: 0.5545 | D34: 0.0544 | E34: 0.0497 | F34: 10 | G34: 10 | H34: 1.548 | I34: 52
A35: CONTROL vs. STEVIA | B35: 0.6089 | C35: 0.553 | D35: 0.0559 | E35: 0.0497 | F35: 10 | G35: 10 | H35: 1.591 | I35: 52
A36: SACAROSA vs. STEVIA | B36: 0.5545 | C36: 0.553 | D36: 0.0015 | E36: 0.0497 | F36: 10 | G36: 10 | H36: 0.04269 | I36: 52
A38: Juvenil
A39: CONTROL vs. SACAROSA | B39: 0.621 | C39: 0.4591 | D39: 0.1619 | E39: 0.05238 | F39: 9 | G39: 9 | H39: 4.371 | I39: 52
A40: CONTROL vs. STEVIA | B40: 0.621 | C40: 0.5953 | D40: 0.0257 | E40: 0.05106 | F40: 9 | G40: 10 | H40: 0.7119 | I40: 52
A41: SACAROSA vs. STEVIA | B41: 0.4591 | C41: 0.5953 | D41: -0.1362 | E41: 0.05106 | F41: 9 | G41: 10 | H41: 3.772 | I41: 52
A43: CONTROL
A44: Juvenil vs. Adulto | B44: 0.621 | C44: 0.6089 | D44: 0.0121 | E44: 0.05106 | F44: 9 | G44: 10 | H44: 0.3352 | I44: 52
A46: SACAROSA
A47: Juvenil vs. Adulto | B47: 0.4591 | C47: 0.5545 | D47: -0.09539 | E47: 0.05106 | F47: 9 | G47: 10 | H47: 2.642 | I47: 52
A49: STEVIA
A50: Juvenil vs. Adulto | B50: 0.5953 | C50: 0.553 | D50: 0.0423 | E50: 0.0497 | F50: 10 | G50: 10 | H50: 1.204 | I50: 52

Sheet S SLR
A1: tasa – s-SLR (isóceles)
A2: Azar = 0,5. Filas = Edad; grupos de columnas = Tratamiento; subcolumnas = animales.
B4: Control | L4: Sacarosa | V4: Stevia
B5: 1 | C5: 2 | D5: 3 | E5: 4 | F5: 5 | G5: 6 | H5: 7 | I5: 8 | J5: 9 | K5: 10 | L5: 1 | M5: 2 | N5: 3 | O5: 4 | P5: 5 | Q5: 6 | R5: 7 | S5: 8 | T5: 9 | U5: 10 | V5: 1 | W5: 2 | X5: 3 | Y5: 4 | Z5: 5 | AA5: 6 | AB5: 7 | AC5: 8 | AD5: 9 | AE5: 10
A6: Juvenil | B6: 0.697 | C6: 0.571 | D6: 0.592 | E6: 0.595 | F6: 0.679 | G6: 0.478 | H6: 0.594 | I6: 0.623 | J6: 0.653 | K6: 0.568 | L6: 0.436 | M6: 0.442 | N6: 0.543 | O6: 0.413 | P6: 0.438 | Q6: 0.254 | R6: 0.582 | S6: 0.301 | T6: 0.586 | V6: 0.41071429 | W6: 0.47706422 | X6: 0.42404372 | Y6: 0.73251029 | Z6: 0.87912088 | AA6: 0.43127962 | AB6: 0.55919395 | AC6: 0.61147541 | AD6: 0.83544304 | AE6: 0.544
A7: Adulto | B7: 0.621 | C7: 0.74 | D7: 0.733 | E7: 0.785 | F7: 0.59 | G7: 0.455 | H7: 0.469 | I7: 0.563 | J7: 0.668 | K7: 0.598 | L7: 0.428 | M7: 0.585 | N7: 0.49 | O7: 0.721 | P7: 0.4 | Q7: 0.356 | R7: 0.301 | S7: 0.288 | T7: 0.276 | U7: 0.746 | V7: 0.5625 | W7: 0.42611684 | X7: 0.3630137 | Y7: 0.37717122 | Z7: 0.5 | AA7: 0.34351145 | AB7: 0.56690141 | AC7: 0.84304933 | AD7: 0.51818182 | AE7: 0.77083333
A9: Bloque a copiar en Prism: B6:AE7 (solo valores).
G10: ctrol | H10: sacarosa | I10: stevia
F11: juv | G11: =AVERAGE(B6:K6) | H11: =AVERAGE(K6:T6) | I11: =AVERAGE(V6:AE6)
F12: adulto | G12: =AVERAGE(B7:K7) | H12: =AVERAGE(L7:U7) | I12: =AVERAGE(V7:AE7)

Sheet ORIGEN
A1: Edad | B1: Tratamiento | C1: Configuración | D1: Subcolumna | E1: Animal | F1: Pestaña | G1: Archivo | H1: Tasa | I1: DI
A2: Adulto | B2: Control | C2: d-SLR (equilátero) | D2: 1 | E2: con 1 | F2: 250509 D2 CtrlSac | G2: SLR_Adulto_2024y2025.xlsx | H2: =IF(INDEX(' D-SLR'!$B$6:$AE$7,2,1)="","",INDEX(' D-SLR'!$B$6:$AE$7,2,1)) | I2: =IF(H2="","",2*H2-1)
A3: Adulto | B3: Control | C3: d-SLR (equilátero) | D3: 2 | E3: con 2 | F3: 250509 D2 CtrlSac | G3: SLR_Adulto_2024y2025.xlsx | H3: =IF(INDEX(' D-SLR'!$B$6:$AE$7,2,2)="","",INDEX(' D-SLR'!$B$6:$AE$7,2,2)) | I3: =IF(H3="","",2*H3-1)
A4: Adulto | B4: Control | C4: d-SLR (equilátero) | D4: 3 | E4: con 3 | F4: 250509 D2 CtrlSac | G4: SLR_Adulto_2024y2025.xlsx | H4: =IF(INDEX(' D-SLR'!$B$6:$AE$7,2,3)="","",INDEX(' D-SLR'!$B$6:$AE$7,2,3)) | I4: =IF(H4="","",2*H4-1)
A5: Adulto | B5: Control | C5: d-SLR (equilátero) | D5: 4 | E5: con 4 | F5: 250509 D2 CtrlSac | G5: SLR_Adulto_2024y2025.xlsx | H5: =IF(INDEX(' D-SLR'!$B$6:$AE$7,2,4)="","",INDEX(' D-SLR'!$B$6:$AE$7,2,4)) | I5: =IF(H5="","",2*H5-1)
A6: Adulto | B6: Control | C6: d-SLR (equilátero) | D6: 5 | E6: con 5 | F6: 250509 D2 CtrlSac | G6: SLR_Adulto_2024y2025.xlsx | H6: =IF(INDEX(' D-SLR'!$B$6:$AE$7,2,5)="","",INDEX(' D-SLR'!$B$6:$AE$7,2,5)) | I6: =IF(H6="","",2*H6-1)
A7: Adulto | B7: Control | C7: d-SLR (equilátero) | D7: 6 | E7: 1 | F7: 251219 D2 Ctrl-dic vasos | G7: SLR_Adulto_2024y2025.xlsx | H7: =IF(INDEX(' D-SLR'!$B$6:$AE$7,2,6)="","",INDEX(' D-SLR'!$B$6:$AE$7,2,6)) | I7: =IF(H7="","",2*H7-1)
A8: Adulto | B8: Control | C8: d-SLR (equilátero) | D8: 7 | E8: 2 | F8: 251219 D2 Ctrl-dic vasos | G8: SLR_Adulto_2024y2025.xlsx | H8: =IF(INDEX(' D-SLR'!$B$6:$AE$7,2,7)="","",INDEX(' D-SLR'!$B$6:$AE$7,2,7)) | I8: =IF(H8="","",2*H8-1)
A9: Adulto | B9: Control | C9: d-SLR (equilátero) | D9: 8 | E9: 3 | F9: 251219 D2 Ctrl-dic vasos | G9: SLR_Adulto_2024y2025.xlsx | H9: =IF(INDEX(' D-SLR'!$B$6:$AE$7,2,8)="","",INDEX(' D-SLR'!$B$6:$AE$7,2,8)) | I9: =IF(H9="","",2*H9-1)
A10: Adulto | B10: Control | C10: d-SLR (equilátero) | D10: 9 | E10: 4 | F10: 251223 D2 Ctrl-dic ranas | G10: SLR_Adulto_2024y2025.xlsx | H10: =IF(INDEX(' D-SLR'!$B$6:$AE$7,2,9)="","",INDEX(' D-SLR'!$B$6:$AE$7,2,9)) | I10: =IF(H10="","",2*H10-1)
A11: Adulto | B11: Control | C11: d-SLR (equilátero) | D11: 10 | E11: 5 | F11: 251223 D2 Ctrl-dic ranas | G11: SLR_Adulto_2024y2025.xlsx | H11: =IF(INDEX(' D-SLR'!$B$6:$AE$7,2,10)="","",INDEX(' D-SLR'!$B$6:$AE$7,2,10)) | I11: =IF(H11="","",2*H11-1)
A12: Adulto | B12: Control | C12: s-SLR (isóceles) | D12: 1 | E12: con 6 | F12: 250509 D2 CtrlSac | G12: SLR_Adulto_2024y2025.xlsx | H12: =IF(INDEX('S SLR'!$B$6:$AE$7,2,1)="","",INDEX('S SLR'!$B$6:$AE$7,2,1)) | I12: =IF(H12="","",2*H12-1)
A13: Adulto | B13: Control | C13: s-SLR (isóceles) | D13: 2 | E13: con 7 | F13: 250509 D2 CtrlSac | G13: SLR_Adulto_2024y2025.xlsx | H13: =IF(INDEX('S SLR'!$B$6:$AE$7,2,2)="","",INDEX('S SLR'!$B$6:$AE$7,2,2)) | I13: =IF(H13="","",2*H13-1)
A14: Adulto | B14: Control | C14: s-SLR (isóceles) | D14: 3 | E14: con 8 | F14: 250509 D2 CtrlSac | G14: SLR_Adulto_2024y2025.xlsx | H14: =IF(INDEX('S SLR'!$B$6:$AE$7,2,3)="","",INDEX('S SLR'!$B$6:$AE$7,2,3)) | I14: =IF(H14="","",2*H14-1)
A15: Adulto | B15: Control | C15: s-SLR (isóceles) | D15: 4 | E15: con 9 | F15: 250509 D2 CtrlSac | G15: SLR_Adulto_2024y2025.xlsx | H15: =IF(INDEX('S SLR'!$B$6:$AE$7,2,4)="","",INDEX('S SLR'!$B$6:$AE$7,2,4)) | I15: =IF(H15="","",2*H15-1)
A16: Adulto | B16: Control | C16: s-SLR (isóceles) | D16: 5 | E16: con NADA | F16: 250509 D2 CtrlSac | G16: SLR_Adulto_2024y2025.xlsx | H16: =IF(INDEX('S SLR'!$B$6:$AE$7,2,5)="","",INDEX('S SLR'!$B$6:$AE$7,2,5)) | I16: =IF(H16="","",2*H16-1)
A17: Adulto | B17: Control | C17: s-SLR (isóceles) | D17: 6 | E17: 4 | F17: 251219 D2 Ctrl-dic vasos | G17: SLR_Adulto_2024y2025.xlsx | H17: =IF(INDEX('S SLR'!$B$6:$AE$7,2,6)="","",INDEX('S SLR'!$B$6:$AE$7,2,6)) | I17: =IF(H17="","",2*H17-1)
A18: Adulto | B18: Control | C18: s-SLR (isóceles) | D18: 7 | E18: 5 | F18: 251219 D2 Ctrl-dic vasos | G18: SLR_Adulto_2024y2025.xlsx | H18: =IF(INDEX('S SLR'!$B$6:$AE$7,2,7)="","",INDEX('S SLR'!$B$6:$AE$7,2,7)) | I18: =IF(H18="","",2*H18-1)
A19: Adulto | B19: Control | C19: s-SLR (isóceles) | D19: 8 | E19: 1 | F19: 251223 D2 Ctrl-dic ranas | G19: SLR_Adulto_2024y2025.xlsx | H19: =IF(INDEX('S SLR'!$B$6:$AE$7,2,8)="","",INDEX('S SLR'!$B$6:$AE$7,2,8)) | I19: =IF(H19="","",2*H19-1)
A20: Adulto | B20: Control | C20: s-SLR (isóceles) | D20: 9 | E20: 2 | F20: 251223 D2 Ctrl-dic ranas | G20: SLR_Adulto_2024y2025.xlsx | H20: =IF(INDEX('S SLR'!$B$6:$AE$7,2,9)="","",INDEX('S SLR'!$B$6:$AE$7,2,9)) | I20: =IF(H20="","",2*H20-1)
A21: Adulto | B21: Control | C21: s-SLR (isóceles) | D21: 10 | E21: 3 | F21: 251223 D2 Ctrl-dic ranas | G21: SLR_Adulto_2024y2025.xlsx | H21: =IF(INDEX('S SLR'!$B$6:$AE$7,2,10)="","",INDEX('S SLR'!$B$6:$AE$7,2,10)) | I21: =IF(H21="","",2*H21-1)
A22: Adulto | B22: Sacarosa | C22: d-SLR (equilátero) | D22: 1 | E22: sac1 | F22: 250509 D2 CtrlSac | G22: SLR_Adulto_2024y2025.xlsx | H22: =IF(INDEX(' D-SLR'!$B$6:$AE$7,2,11)="","",INDEX(' D-SLR'!$B$6:$AE$7,2,11)) | I22: =IF(H22="","",2*H22-1)
A23: Adulto | B23: Sacarosa | C23: d-SLR (equilátero) | D23: 2 | E23: sac2 | F23: 250509 D2 CtrlSac | G23: SLR_Adulto_2024y2025.xlsx | H23: =IF(INDEX(' D-SLR'!$B$6:$AE$7,2,12)="","",INDEX(' D-SLR'!$B$6:$AE$7,2,12)) | I23: =IF(H23="","",2*H23-1)
A24: Adulto | B24: Sacarosa | C24: d-SLR (equilátero) | D24: 3 | E24: sac 3 | F24: 250509 D2 CtrlSac | G24: SLR_Adulto_2024y2025.xlsx | H24: =IF(INDEX(' D-SLR'!$B$6:$AE$7,2,13)="","",INDEX(' D-SLR'!$B$6:$AE$7,2,13)) | I24: =IF(H24="","",2*H24-1)
A25: Adulto | B25: Sacarosa | C25: d-SLR (equilátero) | D25: 4 | E25: sac 4 | F25: 250509 D2 CtrlSac | G25: SLR_Adulto_2024y2025.xlsx | H25: =IF(INDEX(' D-SLR'!$B$6:$AE$7,2,14)="","",INDEX(' D-SLR'!$B$6:$AE$7,2,14)) | I25: =IF(H25="","",2*H25-1)
A26: Adulto | B26: Sacarosa | C26: d-SLR (equilátero) | D26: 5 | E26: sac 5 | F26: 250509 D2 CtrlSac | G26: SLR_Adulto_2024y2025.xlsx | H26: =IF(INDEX(' D-SLR'!$B$6:$AE$7,2,15)="","",INDEX(' D-SLR'!$B$6:$AE$7,2,15)) | I26: =IF(H26="","",2*H26-1)
A27: Adulto | B27: Sacarosa | C27: d-SLR (equilátero) | D27: 6 | E27: sac 1 | F27: 260807 D2 SacStev vasos | G27: SLR_Adulto_2026.xlsx | H27: =IF(INDEX(' D-SLR'!$B$6:$AE$7,2,16)="","",INDEX(' D-SLR'!$B$6:$AE$7,2,16)) | I27: =IF(H27="","",2*H27-1)
A28: Adulto | B28: Sacarosa | C28: d-SLR (equilátero) | D28: 7 | E28: sac 2 | F28: 260807 D2 SacStev vasos | G28: SLR_Adulto_2026.xlsx | H28: =IF(INDEX(' D-SLR'!$B$6:$AE$7,2,17)="","",INDEX(' D-SLR'!$B$6:$AE$7,2,17)) | I28: =IF(H28="","",2*H28-1)
A29: Adulto | B29: Sacarosa | C29: d-SLR (equilátero) | D29: 8 | E29: sac 3 | F29: 260807 D2 SacStev vasos | G29: SLR_Adulto_2026.xlsx | H29: =IF(INDEX(' D-SLR'!$B$6:$AE$7,2,18)="","",INDEX(' D-SLR'!$B$6:$AE$7,2,18)) | I29: =IF(H29="","",2*H29-1)
A30: Adulto | B30: Sacarosa | C30: d-SLR (equilátero) | D30: 9 | E30: 4 | F30: 260811 D2 SacStev ranas | G30: SLR_Adulto_2026.xlsx | H30: =IF(INDEX(' D-SLR'!$B$6:$AE$7,2,19)="","",INDEX(' D-SLR'!$B$6:$AE$7,2,19)) | I30: =IF(H30="","",2*H30-1)
A31: Adulto | B31: Sacarosa | C31: d-SLR (equilátero) | D31: 10 | E31: 5 | F31: 260811 D2 SacStev ranas | G31: SLR_Adulto_2026.xlsx | H31: =IF(INDEX(' D-SLR'!$B$6:$AE$7,2,20)="","",INDEX(' D-SLR'!$B$6:$AE$7,2,20)) | I31: =IF(H31="","",2*H31-1)
A32: Adulto | B32: Sacarosa | C32: s-SLR (isóceles) | D32: 1 | E32: sac 6 | F32: 250509 D2 CtrlSac | G32: SLR_Adulto_2024y2025.xlsx | H32: =IF(INDEX('S SLR'!$B$6:$AE$7,2,11)="","",INDEX('S SLR'!$B$6:$AE$7,2,11)) | I32: =IF(H32="","",2*H32-1)
A33: Adulto | B33: Sacarosa | C33: s-SLR (isóceles) | D33: 2 | E33: sac7 | F33: 250509 D2 CtrlSac | G33: SLR_Adulto_2024y2025.xlsx | H33: =IF(INDEX('S SLR'!$B$6:$AE$7,2,12)="","",INDEX('S SLR'!$B$6:$AE$7,2,12)) | I33: =IF(H33="","",2*H33-1)
A34: Adulto | B34: Sacarosa | C34: s-SLR (isóceles) | D34: 3 | E34: sac8 | F34: 250509 D2 CtrlSac | G34: SLR_Adulto_2024y2025.xlsx | H34: =IF(INDEX('S SLR'!$B$6:$AE$7,2,13)="","",INDEX('S SLR'!$B$6:$AE$7,2,13)) | I34: =IF(H34="","",2*H34-1)
A35: Adulto | B35: Sacarosa | C35: s-SLR (isóceles) | D35: 4 | E35: sac 9 | F35: 250509 D2 CtrlSac | G35: SLR_Adulto_2024y2025.xlsx | H35: =IF(INDEX('S SLR'!$B$6:$AE$7,2,14)="","",INDEX('S SLR'!$B$6:$AE$7,2,14)) | I35: =IF(H35="","",2*H35-1)
A36: Adulto | B36: Sacarosa | C36: s-SLR (isóceles) | D36: 5 | E36: sac nada | F36: 250509 D2 CtrlSac | G36: SLR_Adulto_2024y2025.xlsx | H36: =IF(INDEX('S SLR'!$B$6:$AE$7,2,15)="","",INDEX('S SLR'!$B$6:$AE$7,2,15)) | I36: =IF(H36="","",2*H36-1)
A37: Adulto | B37: Sacarosa | C37: s-SLR (isóceles) | D37: 6 | E37: sac 4 | F37: 260807 D2 SacStev vasos | G37: SLR_Adulto_2026.xlsx | H37: =IF(INDEX('S SLR'!$B$6:$AE$7,2,16)="","",INDEX('S SLR'!$B$6:$AE$7,2,16)) | I37: =IF(H37="","",2*H37-1)
A38: Adulto | B38: Sacarosa | C38: s-SLR (isóceles) | D38: 7 | E38: sac 5 | F38: 260807 D2 SacStev vasos | G38: SLR_Adulto_2026.xlsx | H38: =IF(INDEX('S SLR'!$B$6:$AE$7,2,17)="","",INDEX('S SLR'!$B$6:$AE$7,2,17)) | I38: =IF(H38="","",2*H38-1)
A39: Adulto | B39: Sacarosa | C39: s-SLR (isóceles) | D39: 8 | E39: 1 | F39: 260811 D2 SacStev ranas | G39: SLR_Adulto_2026.xlsx | H39: =IF(INDEX('S SLR'!$B$6:$AE$7,2,18)="","",INDEX('S SLR'!$B$6:$AE$7,2,18)) | I39: =IF(H39="","",2*H39-1)
A40: Adulto | B40: Sacarosa | C40: s-SLR (isóceles) | D40: 9 | E40: 2 | F40: 260811 D2 SacStev ranas | G40: SLR_Adulto_2026.xlsx | H40: =IF(INDEX('S SLR'!$B$6:$AE$7,2,19)="","",INDEX('S SLR'!$B$6:$AE$7,2,19)) | I40: =IF(H40="","",2*H40-1)
...

Sheet anova
A2: Table Analyzed | B2: S-slr TASA EXPLORACIÓN
A4: Two-way ANOVA | B4: Ordinary
A5: Alpha | B5: 0.05
A7: Source of Variation | B7: % of total variation | C7: P value | D7: P value summary | E7: Significant?
A8: Interaction | B8: 1.567 | C8: 0.5925 | D8: ns | E8: No
A9: Row Factor | B9: 0.1166 | C9: 0.7802 | D9: ns | E9: No
A10: Column Factor | B10: 19.79 | C10: 0.0026 | D10: ** | E10: Yes
A12: ANOVA table | B12: SS (Type III) | C12: DF | D12: MS | E12: F (DFn, DFd) | F12: P value
A13: Interaction | B13: 0.02085 | C13: 2 | D13: 0.01043 | E13: F (2, 53) = 0.5286 | F13: P=0.5925
A14: Row Factor | B14: 0.001551 | C14: 1 | D14: 0.001551 | E14: F (1, 53) = 0.07864 | F14: P=0.7802
A15: Column Factor | B15: 0.2633 | C15: 2 | D15: 0.1317 | E15: F (2, 53) = 6.675 | F15: P=0.0026
A16: Residual | B16: 1.045 | C16: 53 | D16: 0.01973
A17: Total | B17: 1.33 | C17: 58
A19: Difference between row means
A20: Predicted (LS) mean of Juvenil | B20: 0.5464
A21: Predicted (LS) mean of Adulto | B21: 0.5362
A22: Difference between predicted means | B22: 0.01026
A23: SE of difference | B23: 0.0366
A24: 95% CI of difference | B24: -0.06314 to 0.08367
A26: Data summary
A27: Number of columns (Column Factor) | B27: 3
A28: Number of rows (Row Factor) | B28: 2
A29: Number of values | B29: 59

Sheet s slr multiple
A2: Compare cell means with others in its row and its column
A4: Number of families | B4: 5 | G4: multiple comparisons
A5: Number of comparisons per row family | B5: 3
A6: Number of comparisons per column family | B6: 1
A7: Alpha | B7: 0.05
A9: Tukey's multiple comparisons test | B9: Predicted (LS) Mean diff. | C9: 95.00% CI of diff. | D9: Below threshold? | E9: Summary | F9: Adjusted P Value
A11: Adulto
A12: Control vs. Sacarosa | B12: 0.1631 | C12: 0.01165 to 0.3146 | D12: Yes | E12: * | F12: 0.0321
A13: Control vs. Stevia | B13: 0.095 | C13: -0.05645 to 0.2465 | D13: No | E13: ns | F13: 0.2933
A14: Sacarosa vs. Stevia | B14: -0.0681 | C14: -0.2196 to 0.08335 | D14: No | E14: ns | F14: 0.528
A16: Juvenil
A17: Control vs. Sacarosa | B17: 0.1611 | C17: 0.005507 to 0.3167 | D17: Yes | E17: * | F17: 0.0409
A18: Control vs. Stevia | B18: 0.0146 | C18: -0.1369 to 0.1661 | D18: No | E18: ns | F18: 0.9707
A19: Sacarosa vs. Stevia | B19: -0.1465 | C19: -0.3021 to 0.009093 | D19: No | E19: ns | F19: 0.0689
A21: Control
A22: Juvenil vs. Adulto | B22: -0.0172 | C22: -0.1432 to 0.1088 | D22: No | E22: ns | F22: 0.7853
A24: Sacarosa
A25: Juvenil vs. Adulto | B25: -0.01521 | C25: -0.1446 to 0.1142 | D25: No | E25: ns | F25: 0.8146
A27: Stevia
A28: Juvenil vs. Adulto | B28: 0.0632 | C28: -0.06278 to 0.1892 | D28: No | E28: ns | F28: 0.3189
A31: Test details | B31: Predicted (LS) Mean 1 | C31: Predicted (LS) Mean 2 | D31: Predicted (LS) Mean diff. | E31: SE of diff. | F31: N1 | G31: N2 | H31: q | I31: DF
A33: Adulto
A34: Control vs. Sacarosa | B34: 0.6222 | C34: 0.4591 | D34: 0.1631 | E34: 0.06281 | F34: 10 | G34: 10 | H34: 3.672 | I34: 53
A35: Control vs. Stevia | B35: 0.6222 | C35: 0.5272 | D35: 0.095 | E35: 0.06281 | F35: 10 | G35: 10 | H35: 2.139 | I35: 53
A36: Sacarosa vs. Stevia | B36: 0.4591 | C36: 0.5272 | D36: -0.0681 | E36: 0.06281 | F36: 10 | G36: 10 | H36: 1.533 | I36: 53
A38: Juvenil
A39: Control vs. Sacarosa | B39: 0.605 | C39: 0.4439 | D39: 0.1611 | E39: 0.06453 | F39: 10 | G39: 9 | H39: 3.531 | I39: 53
A40: Control vs. Stevia | B40: 0.605 | C40: 0.5904 | D40: 0.0146 | E40: 0.06281 | F40: 10 | G40: 10 | H40: 0.3287 | I40: 53
A41: Sacarosa vs. Stevia | B41: 0.4439 | C41: 0.5904 | D41: -0.1465 | E41: 0.06453 | F41: 9 | G41: 10 | H41: 3.211 | I41: 53
A43: Control
A44: Juvenil vs. Adulto | B44: 0.605 | C44: 0.6222 | D44: -0.0172 | E44: 0.06281 | F44: 10 | G44: 10 | H44: 0.3873 | I44: 53
A46: Sacarosa
A47: Juvenil vs. Adulto | B47: 0.4439 | C47: 0.4591 | D47: -0.01521 | E47: 0.06453 | F47: 9 | G47: 10 | H47: 0.3333 | I47: 53
A49: Stevia
A50: Juvenil vs. Adulto | B50: 0.5904 | C50: 0.5272 | D50: 0.0632 | E50: 0.06281 | F50: 10 | G50: 10 | H50: 1.423 | I50: 53
