Workbook

Sheet Resumen D1
A1: SLR – Día 1 (muestreo): exploración total y preferencia de posición por grupo
A3: Qué es | B3: Control de la fase de codificación. El día 1 hay tres objetos idénticos y ninguno es novedoso, así que no se calcula DI: se verifica que los grupos hayan explorado de forma comparable y sin preferencia previa por una posición.
A4: Exploración total D1 | B4: Suma del tiempo explorando los tres objetos (s). Todas las sesiones del día 1 duran 10 min, así que es comparable entre grupos (no con el día 2, que dura 5 min y tiene 2 objetos).
A5: % en objeto fijo | B5: Tiempo en el objeto que queda en su lugar en el test (será el familiar) / exploración total. Azar = 33,3 %. Valores por encima indican que el grupo ya prefería esa posición antes del test.
A6: n | B6: Animales por grupo y configuración (cada animal aparece una vez por configuración), igual que en el análisis del día 2.
A8: Grupo | B8: d-SLR (equilátero) | E8: s-SLR (isósceles)
B9: n | C9: Exploración total (s) | D9: % en objeto fijo | E9: n | F9: Exploración total (s) | G9: % en objeto fijo
A10: Juvenil – Control | B10: =COUNTIFS('Datos por animal'!$C:$C,$A10,'Datos por animal'!$D:$D,"d-SLR (equilátero)") -> 9 | C10: =AVERAGEIFS('Datos por animal'!$O:$O,'Datos por animal'!$C:$C,$A10,'Datos por animal'!$D:$D,"d-SLR (equilátero)") -> 30.633333 | D10: =AVERAGEIFS('Datos por animal'!$P:$P,'Datos por animal'!$C:$C,$A10,'Datos por animal'!$D:$D,"d-SLR (equilátero)") -> 0.31851689 | E10: =COUNTIFS('Datos por animal'!$C:$C,$A10,'Datos por animal'!$D:$D,"s-SLR (isósceles)") -> 10 | F10: =AVERAGEIFS('Datos por animal'!$O:$O,'Datos por animal'!$C:$C,$A10,'Datos por animal'!$D:$D,"s-SLR (isósceles)") -> 30.6 | G10: =AVERAGEIFS('Datos por animal'!$P:$P,'Datos por animal'!$C:$C,$A10,'Datos por animal'!$D:$D,"s-SLR (isósceles)") -> 0.33009801
A11: Juvenil – Sacarosa | B11: =COUNTIFS('Datos por animal'!$C:$C,$A11,'Datos por animal'!$D:$D,"d-SLR (equilátero)") -> 9 | C11: =AVERAGEIFS('Datos por animal'!$O:$O,'Datos por animal'!$C:$C,$A11,'Datos por animal'!$D:$D,"d-SLR (equilátero)") -> 50.722222 | D11: =AVERAGEIFS('Datos por animal'!$P:$P,'Datos por animal'!$C:$C,$A11,'Datos por animal'!$D:$D,"d-SLR (equilátero)") -> 0.33397342 | E11: =COUNTIFS('Datos por animal'!$C:$C,$A11,'Datos por animal'!$D:$D,"s-SLR (isósceles)") -> 9 | F11: =AVERAGEIFS('Datos por animal'!$O:$O,'Datos por animal'!$C:$C,$A11,'Datos por animal'!$D:$D,"s-SLR (isósceles)") -> 58.222222 | G11: =AVERAGEIFS('Datos por animal'!$P:$P,'Datos por animal'!$C:$C,$A11,'Datos por animal'!$D:$D,"s-SLR (isósceles)") -> 0.35415745
A12: Juvenil – Stevia | B12: =COUNTIFS('Datos por animal'!$C:$C,$A12,'Datos por animal'!$D:$D,"d-SLR (equilátero)") -> 10 | C12: =AVERAGEIFS('Datos por animal'!$O:$O,'Datos por animal'!$C:$C,$A12,'Datos por animal'!$D:$D,"d-SLR (equilátero)") -> 43.43 | D12: =AVERAGEIFS('Datos por animal'!$P:$P,'Datos por animal'!$C:$C,$A12,'Datos por animal'!$D:$D,"d-SLR (equilátero)") -> 0.34155798 | E12: =COUNTIFS('Datos por animal'!$C:$C,$A12,'Datos por animal'!$D:$D,"s-SLR (isósceles)") -> 10 | F12: =AVERAGEIFS('Datos por animal'!$O:$O,'Datos por animal'!$C:$C,$A12,'Datos por animal'!$D:$D,"s-SLR (isósceles)") -> 39.96 | G12: =AVERAGEIFS('Datos por animal'!$P:$P,'Datos por animal'!$C:$C,$A12,'Datos por animal'!$D:$D,"s-SLR (isósceles)") -> 0.3947219
A13: Adulto – Control | B13: =COUNTIFS('Datos por animal'!$C:$C,$A13,'Datos por animal'!$D:$D,"d-SLR (equilátero)") -> 10 | C13: =AVERAGEIFS('Datos por animal'!$O:$O,'Datos por animal'!$C:$C,$A13,'Datos por animal'!$D:$D,"d-SLR (equilátero)") -> 42.88 | D13: =AVERAGEIFS('Datos por animal'!$P:$P,'Datos por animal'!$C:$C,$A13,'Datos por animal'!$D:$D,"d-SLR (equilátero)") -> 0.36687766 | E13: =COUNTIFS('Datos por animal'!$C:$C,$A13,'Datos por animal'!$D:$D,"s-SLR (isósceles)") -> 10 | F13: =AVERAGEIFS('Datos por animal'!$O:$O,'Datos por animal'!$C:$C,$A13,'Datos por animal'!$D:$D,"s-SLR (isósceles)") -> 30.54 | G13: =AVERAGEIFS('Datos por animal'!$P:$P,'Datos por animal'!$C:$C,$A13,'Datos por animal'!$D:$D,"s-SLR (isósceles)") -> 0.45126399
A14: Adulto – Sacarosa | B14: =COUNTIFS('Datos por animal'!$C:$C,$A14,'Datos por animal'!$D:$D,"d-SLR (equilátero)") -> 10 | C14: =AVERAGEIFS('Datos por animal'!$O:$O,'Datos por animal'!$C:$C,$A14,'Datos por animal'!$D:$D,"d-SLR (equilátero)") -> 37.18 | D14: =AVERAGEIFS('Datos por animal'!$P:$P,'Datos por animal'!$C:$C,$A14,'Datos por animal'!$D:$D,"d-SLR (equilátero)") -> 0.36713239 | E14: =COUNTIFS('Datos por animal'!$C:$C,$A14,'Datos por animal'!$D:$D,"s-SLR (isósceles)") -> 10 | F14: =AVERAGEIFS('Datos por animal'!$O:$O,'Datos por animal'!$C:$C,$A14,'Datos por animal'!$D:$D,"s-SLR (isósceles)") -> 37.77 | G14: =AVERAGEIFS('Datos por animal'!$P:$P,'Datos por animal'!$C:$C,$A14,'Datos por animal'!$D:$D,"s-SLR (isósceles)") -> 0.4779685
A15: Adulto – Stevia | B15: =COUNTIFS('Datos por animal'!$C:$C,$A15,'Datos por animal'!$D:$D,"d-SLR (equilátero)") -> 10 | C15: =AVERAGEIFS('Datos por animal'!$O:$O,'Datos por animal'!$C:$C,$A15,'Datos por animal'!$D:$D,"d-SLR (equilátero)") -> 56.07 | D15: =AVERAGEIFS('Datos por animal'!$P:$P,'Datos por animal'!$C:$C,$A15,'Datos por animal'!$D:$D,"d-SLR (equilátero)") -> 0.33969997 | E15: =COUNTIFS('Datos por animal'!$C:$C,$A15,'Datos por animal'!$D:$D,"s-SLR (isósceles)") -> 10 | F15: =AVERAGEIFS('Datos por animal'!$O:$O,'Datos por animal'!$C:$C,$A15,'Datos por animal'!$D:$D,"s-SLR (isósceles)") -> 55.44 | G15: =AVERAGEIFS('Datos por animal'!$P:$P,'Datos por animal'!$C:$C,$A15,'Datos por animal'!$D:$D,"s-SLR (isósceles)") -> 0.38003845
A17: Valores: media del grupo (sin SEM ni estadística). Datos individuales en "Datos por animal"; columnas listas para pegar en Prism en la pestaña "Prism".
A18: Asignación de grupos: Juvenil – Control incluye los lotes de junio y octubre 2025; Adulto – Control, mayo y diciembre 2025; Sacarosa y Stevia incluyen las cohortes 2024/2025 y 2026.
A19: Objeto fijo asumido (no anotado en la hoja original): Zona 2 en la tanda equilátero del 08/05/2025; Zona 1 en equilátero de adultos 2026 y del par 1 juvenil 2026. A confirmar.
A20: Hay 8 sesiones de menos de ~10 min (cortes anticipados del registro, de 402 a 589 s) y 5 sin dato de duración (control juvenil oct 2025, vasos), marcadas en "Datos por animal"; no se excluyeron.
A21: Excluido 1 registro duplicado: "con 1 raya" (repetición del muestreo de con 1, adulto mayo 2025).

Sheet Datos por animal
A1: SLR – Día 1 (muestreo, 3 objetos idénticos) – datos por animal
A2: Una fila por animal y configuración. Columnas L–N: tiempo de exploración manual (time pressed de AnyMaze©) de cada objeto. Celdas amarillas = fórmulas. Sin exclusiones por umbral; valores tal cual del registro.
A4: Edad | B4: Tratamiento | C4: Grupo | D4: Configuración | E4: Lote / cohorte | F4: Objetos | G4: Fecha D1 | H4: Pestaña de origen | I4: Animal (etiqueta original) | J4: Duración sesión (s) | K4: Zona del objeto fijo | L4: t objeto fijo (s) (queda en el test) | M4: t objeto desplazado 1 (s) | N4: t objeto desplazado 2 (s) | O4: Exploración total D1 (s) | P4: % tiempo en objeto fijo | Q4: Zonas de los objetos desplazados
A5: Juvenil | B5: Control | C5: Juvenil – Control | D5: d-SLR (equilátero) | E5: Ctrl/Stevia jun 2025 | F5: — | G5: 05/06/2025 | H5: 250605 D1 Ctrl+Stevia | I5: CON 1 | J5: 598.8 | K5: Zona 1 | L5: 8.6 | M5: 17.8 | N5: 19.2 | O5: =L5+M5+N5 -> 45.6 | P5: =IF(O5=0,"",L5/O5) -> 0.18859649 | Q5: Zona 2 / Zona 3
A6: Juvenil | B6: Control | C6: Juvenil – Control | D6: d-SLR (equilátero) | E6: Ctrl/Stevia jun 2025 | F6: — | G6: 05/06/2025 | H6: 250605 D1 Ctrl+Stevia | I6: CON 2 | J6: 592.7 | K6: Zona 1 | L6: 10.8 | M6: 22.5 | N6: 21 | O6: =L6+M6+N6 -> 54.3 | P6: =IF(O6=0,"",L6/O6) -> 0.19889503 | Q6: Zona 2 / Zona 3
A7: Juvenil | B7: Control | C7: Juvenil – Control | D7: d-SLR (equilátero) | E7: Ctrl/Stevia jun 2025 | F7: — | G7: 05/06/2025 | H7: 250605 D1 Ctrl+Stevia | I7: CON 3 | J7: 600 | K7: Zona 1 | L7: 7.2 | M7: 10.3 | N7: 9.4 | O7: =L7+M7+N7 -> 26.9 | P7: =IF(O7=0,"",L7/O7) -> 0.26765799 | Q7: Zona 2 / Zona 3
A8: Juvenil | B8: Control | C8: Juvenil – Control | D8: d-SLR (equilátero) | E8: Ctrl/Stevia jun 2025 | F8: — | G8: 05/06/2025 | H8: 250605 D1 Ctrl+Stevia | I8: CON 4 | J8: 598.8 | K8: Zona 1 | L8: 12.9 | M8: 4.8 | N8: 7.6 | O8: =L8+M8+N8 -> 25.3 | P8: =IF(O8=0,"",L8/O8) -> 0.50988142 | Q8: Zona 2 / Zona 3
A9: Juvenil | B9: Control | C9: Juvenil – Control | D9: d-SLR (equilátero) | E9: Control oct 2025 | F9: Vasos | G9: 30/10/2025 | H9: 251030 D1 Ctrl-oct vasos | I9: 1 | J9: sin dato | K9: Zona 1 | L9: 12.8 | M9: 11.4 | N9: 9.6 | O9: =L9+M9+N9 -> 33.8 | P9: =IF(O9=0,"",L9/O9) -> 0.37869822 | Q9: Zona 2 / Zona 3
A10: Juvenil | B10: Control | C10: Juvenil – Control | D10: d-SLR (equilátero) | E10: Control oct 2025 | F10: Vasos | G10: 30/10/2025 | H10: 251030 D1 Ctrl-oct vasos | I10: 2 | J10: sin dato | K10: Zona 1 | L10: 4.8 | M10: 10.7 | N10: 15.1 | O10: =L10+M10+N10 -> 30.6 | P10: =IF(O10=0,"",L10/O10) -> 0.15686275 | Q10: Zona 2 / Zona 3
A11: Juvenil | B11: Control | C11: Juvenil – Control | D11: d-SLR (equilátero) | E11: Control oct 2025 | F11: Vasos | G11: 30/10/2025 | H11: 251030 D1 Ctrl-oct vasos | I11: 3 | J11: sin dato | K11: Zona 1 | L11: 13.3 | M11: 12.4 | N11: 5.4 | O11: =L11+M11+N11 -> 31.1 | P11: =IF(O11=0,"",L11/O11) -> 0.42765273 | Q11: Zona 2 / Zona 3
A12: Juvenil | B12: Control | C12: Juvenil – Control | D12: d-SLR (equilátero) | E12: Control oct 2025 | F12: Ranas | G12: 03/11/2025 | H12: 251103 D1 Ctrl-oct ranas | I12: 4 | J12: 600 | K12: Zona 1 | L12: 3.4 | M12: 1.7 | N12: 1.5 | O12: =L12+M12+N12 -> 6.6 | P12: =IF(O12=0,"",L12/O12) -> 0.51515152 | Q12: Zona 2EQ / Zona 3EQ
A13: Juvenil | B13: Control | C13: Juvenil – Control | D13: d-SLR (equilátero) | E13: Control oct 2025 | F13: Ranas | G13: 03/11/2025 | H13: 251103 D1 Ctrl-oct ranas | I13: 5 | J13: 600 | K13: Zona 1 | L13: 4.8 | M13: 5.5 | N13: 11.2 | O13: =L13+M13+N13 -> 21.5 | P13: =IF(O13=0,"",L13/O13) -> 0.22325581 | Q13: Zona 2EQ / Zona 3EQ
A14: Juvenil | B14: Control | C14: Juvenil – Control | D14: s-SLR (isósceles) | E14: Ctrl/Stevia jun 2025 | F14: — | G14: 05/06/2025 | H14: 250605 D1 Ctrl+Stevia | I14: con 5 | J14: 595.3 | K14: Zona 1 | L14: 18.8 | M14: 6.4 | N14: 12.4 | O14: =L14+M14+N14 -> 37.6 | P14: =IF(O14=0,"",L14/O14) -> 0.5 | Q14: Zona 2 / Zona 3
A15: Juvenil | B15: Control | C15: Juvenil – Control | D15: s-SLR (isósceles) | E15: Ctrl/Stevia jun 2025 | F15: — | G15: 05/06/2025 | H15: 250605 D1 Ctrl+Stevia | I15: con 6 | J15: 598.5 | K15: Zona 1 | L15: 12.5 | M15: 12.7 | N15: 11.3 | O15: =L15+M15+N15 -> 36.5 | P15: =IF(O15=0,"",L15/O15) -> 0.34246575 | Q15: Zona 2 / Zona 3
A16: Juvenil | B16: Control | C16: Juvenil – Control | D16: s-SLR (isósceles) | E16: Ctrl/Stevia jun 2025 | F16: — | G16: 05/06/2025 | H16: 250605 D1 Ctrl+Stevia | I16: con 7 | J16: 598.8 | K16: Zona 1 | L16: 5 | M16: 7.8 | N16: 10 | O16: =L16+M16+N16 -> 22.8 | P16: =IF(O16=0,"",L16/O16) -> 0.21929825 | Q16: Zona 2 / Zona 3
A17: Juvenil | B17: Control | C17: Juvenil – Control | D17: s-SLR (isósceles) | E17: Ctrl/Stevia jun 2025 | F17: — | G17: 05/06/2025 | H17: 250605 D1 Ctrl+Stevia | I17: con 8 | J17: 598.4 | K17: Zona 1 | L17: 11.8 | M17: 9.7 | N17: 13.8 | O17: =L17+M17+N17 -> 35.3 | P17: =IF(O17=0,"",L17/O17) -> 0.33427762 | Q17: Zona 2 / Zona 3
A18: Juvenil | B18: Control | C18: Juvenil – Control | D18: s-SLR (isósceles) | E18: Ctrl/Stevia jun 2025 | F18: — | G18: 05/06/2025 | H18: 250605 D1 Ctrl+Stevia | I18: con 9 | J18: 590.5 | K18: Zona 1 | L18: 6.9 | M18: 13.2 | N18: 8.8 | O18: =L18+M18+N18 -> 28.9 | P18: =IF(O18=0,"",L18/O18) -> 0.23875433 | Q18: Zona 2 / Zona 3
A19: Juvenil | B19: Control | C19: Juvenil – Control | D19: s-SLR (isósceles) | E19: Control oct 2025 | F19: Vasos | G19: 30/10/2025 | H19: 251030 D1 Ctrl-oct vasos | I19: 4 | J19: sin dato | K19: Zona 1 | L19: 31 | M19: 9.9 | N19: 8.4 | O19: =L19+M19+N19 -> 49.3 | P19: =IF(O19=0,"",L19/O19) -> 0.62880325 | Q19: Zona 2B / Zona 3B
A20: Juvenil | B20: Control | C20: Juvenil – Control | D20: s-SLR (isósceles) | E20: Control oct 2025 | F20: Vasos | G20: 30/10/2025 | H20: 251030 D1 Ctrl-oct vasos | I20: 5 | J20: sin dato | K20: Zona 1 | L20: 11 | M20: 9.4 | N20: 10.8 | O20: =L20+M20+N20 -> 31.2 | P20: =IF(O20=0,"",L20/O20) -> 0.3525641 | Q20: Zona 2B / Zona 3B
A21: Juvenil | B21: Control | C21: Juvenil – Control | D21: s-SLR (isósceles) | E21: Control oct 2025 | F21: Ranas | G21: 03/11/2025 | H21: 251103 D1 Ctrl-oct ranas | I21: 1 | J21: 600 | K21: Zona 1 | L21: 10.1 | M21: 8.8 | N21: 7.1 | O21: =L21+M21+N21 -> 26 | P21: =IF(O21=0,"",L21/O21) -> 0.38846154 | Q21: Zona 2 / Zona 3
A22: Juvenil | B22: Control | C22: Juvenil – Control | D22: s-SLR (isósceles) | E22: Control oct 2025 | F22: Ranas | G22: 03/11/2025 | H22: 251103 D1 Ctrl-oct ranas | I22: 2 | J22: 600 | K22: Zona 1 | L22: 3.6 | M22: 13.6 | N22: 9.4 | O22: =L22+M22+N22 -> 26.6 | P22: =IF(O22=0,"",L22/O22) -> 0.13533835 | Q22: Zona 2 / Zona 3
A23: Juvenil | B23: Control | C23: Juvenil – Control | D23: s-SLR (isósceles) | E23: Control oct 2025 | F23: Ranas | G23: 03/11/2025 | H23: 251103 D1 Ctrl-oct ranas | I23: 3 | J23: 533.1 | K23: Zona 1 | L23: 1.9 | M23: 2.3 | N23: 7.6 | O23: =L23+M23+N23 -> 11.8 | P23: =IF(O23=0,"",L23/O23) -> 0.16101695 | Q23: Zona 2 / Zona 3
A24: Juvenil | B24: Sacarosa | C24: Juvenil – Sacarosa | D24: d-SLR (equilátero) | E24: Sacarosa jun 2025 | F24: — | G24: 26/06/2025 | H24: 250626 D1 Sacarosa | I24: 1 | J24: 599.1 | K24: Zona 2 | L24: 12.2 | M24: 23.4 | N24: 12.1 | O24: =L24+M24+N24 -> 47.7 | P24: =IF(O24=0,"",L24/O24) -> 0.2557652 | Q24: Zona 1 / Zona 3
A25: Juvenil | B25: Sacarosa | C25: Juvenil – Sacarosa | D25: d-SLR (equilátero) | E25: Sacarosa jun 2025 | F25: — | G25: 26/06/2025 | H25: 250626 D1 Sacarosa | I25: 2 | J25: 599.1 | K25: Zona 2 | L25: 33.6 | M25: 17.4 | N25: 26.6 | O25: =L25+M25+N25 -> 77.6 | P25: =IF(O25=0,"",L25/O25) -> 0.43298969 | Q25: Zona 1 / Zona 3
A26: Juvenil | B26: Sacarosa | C26: Juvenil – Sacarosa | D26: d-SLR (equilátero) | E26: Sacarosa jun 2025 | F26: — | G26: 26/06/2025 | H26: 250626 D1 Sacarosa | I26: 3 | J26: 597.5 | K26: Zona 2 | L26: 27.4 | M26: 16.2 | N26: 26.5 | O26: =L26+M26+N26 -> 70.1 | P26: =IF(O26=0,"",L26/O26) -> 0.39087019 | Q26: Zona 1 / Zona 3
A27: Juvenil | B27: Sacarosa | C27: Juvenil – Sacarosa | D27: d-SLR (equilátero) | E27: Sacarosa jun 2025 | F27: — | G27: 26/06/2025 | H27: 250626 D1 Sacarosa | I27: 4 | J27: 597.7 | K27: Zona 2 | L27: 16.8 | M27: 11.8 | N27: 11.1 | O27: =L27+M27+N27 -> 39.7 | P27: =IF(O27=0,"",L27/O27) -> 0.4231738 | Q27: Zona 1 / Zona 3
A28: Juvenil | B28: Sacarosa | C28: Juvenil – Sacarosa | D28: d-SLR (equilátero) | E28: Sac/Stevia 2026 par 1 | F28: Vasos | G28: 19/07/2026 | H28: 260719 D1 Par1 vasos | I28: JUV SAC 1 | J28: 594.1 | K28: ZONA 1 | L28: 19.5 | M28: 18.2 | N28: 13.9 | O28: =L28+M28+N28 -> 51.6 | P28: =IF(O28=0,"",L28/O28) -> 0.37790698 | Q28: ZONA 2 / ZONA 3
A29: Juvenil | B29: Sacarosa | C29: Juvenil – Sacarosa | D29: d-SLR (equilátero) | E29: Sac/Stevia 2026 par 1 | F29: Vasos | G29: 19/07/2026 | H29: 260719 D1 Par1 vasos | I29: JUV SAC 2 | J29: 600 | K29: ZONA 1 | L29: 21.5 | M29: 24.5 | N29: 14.5 | O29: =L29+M29+N29 -> 60.5 | P29: =IF(O29=0,"",L29/O29) -> 0.3553719 | Q29: ZONA 2 / ZONA 3
A30: Juvenil | B30: Sacarosa | C30: Juvenil – Sacarosa | D30: d-SLR (equilátero) | E30: Sac/Stevia 2026 par 1 | F30: Vasos | G30: 19/07/2026 | H30: 260719 D1 Par1 vasos | I30: JUV SAC 3 | J30: 600 | K30: ZONA 1 | L30: 15.3 | M30: 22.1 | N30: 19.5 | O30: =L30+M30+N30 -> 56.9 | P30: =IF(O30=0,"",L30/O30) -> 0.26889279 | Q30: ZONA 2 / ZONA 3
A31: Juvenil | B31: Sacarosa | C31: Juvenil – Sacarosa | D31: d-SLR (equilátero) | E31: Sac/Stevia 2026 par 2 | F31: Ranas | G31: 23/07/2026 | H31: 260723 D1 Par2 ranas | I31: sac 4 | J31: 600 | K31: Zona 3 | L31: 12.6 | M31: 8.3 | N31: 10 | O31: =L31+M31+N31 -> 30.9 | P31: =IF(O31=0,"",L31/O31) -> 0.40776699 | Q31: Zona 2 / Zona 1
A32: Juvenil | B32: Sacarosa | C32: Juvenil – Sacarosa | D32: d-SLR (equilátero) | E32: Sac/Stevia 2026 par 2 | F32: Ranas | G32: 23/07/2026 | H32: 260723 D1 Par2 ranas | I32: sac 5 | J32: 600 | K32: Zona 3 | L32: 2 | M32: 4.3 | N32: 15.2 | O32: =L32+M32+N32 -> 21.5 | P32: =IF(O32=0,"",L32/O32) -> 0.093023256 | Q32: Zona 2 / Zona 1
... A121: Adulto | B121: Stevia | C121: Adulto – Stevia | D121: s-SLR (isósceles) | E121: Sac/Stevia 2026 | F121: Vasos | G121: 06/08/2026 | H121: 260806 D1 SacStev vasos | I121: STEV 5 | J121: 600 | K121: Zona 1 | L121: 27.3 | M121: 23.8 | N121: 18.2 | O121: =L121+M121+N121 -> 69.3 | P121: =IF(O121=0,"",L121/O121) -> 0.39393939 | Q121: Zona 2 / Zona 3
A123: Exploración total D1 = suma de los tres objetos. % en objeto fijo = t objeto fijo / exploración total; azar = 33,3 % (3 objetos idénticos).
A124: Duración en naranja = sesión de menos de 10 min (corte anticipado del registro); la exploración total de esos animales puede estar subestimada. Lote control oct 2025 (vasos): sin dato de duración en el original.
A125: Excluido: "con 1 raya" (pestaña 250508 D1 CtrlSac isoc) = repetición del muestreo de con 1; se usa el registro de con 1 de la tanda equilátero, que es su configuración en el test.

Sheet Prism
A1: Valores individuales del día 1 por grupo (columnas), listos para copiar a Prism
A2: Cada celda está vinculada a "Datos por animal". Cuatro bloques: exploración total y % en objeto fijo, en d-SLR y en s-SLR.
A4: Exploración total D1 (s) – d-SLR (equilátero)
A5: Juvenil – Control | B5: Juvenil – Sacarosa | C5: Juvenil – Stevia | D5: Adulto – Control | E5: Adulto – Sacarosa | F5: Adulto – Stevia
A6: ='Datos por animal'!O5 -> 45.6 | B6: ='Datos por animal'!O24 -> 47.7 | C6: ='Datos por animal'!O42 -> 22.8 | D6: ='Datos por animal'!O62 -> 24.5 | E6: ='Datos por animal'!O82 -> 42.6 | F6: ='Datos por animal'!O102 -> 81.1
A7: ='Datos por animal'!O6 -> 54.3 | B7: ='Datos por animal'!O25 -> 77.6 | C7: ='Datos por animal'!O43 -> 19 | D7: ='Datos por animal'!O63 -> 44.3 | E7: ='Datos por animal'!O83 -> 29 | F7: ='Datos por animal'!O103 -> 49.7
A8: ='Datos por animal'!O7 -> 26.9 | B8: ='Datos por animal'!O26 -> 70.1 | C8: ='Datos por animal'!O44 -> 24.4 | D8: ='Datos por animal'!O64 -> 59.8 | E8: ='Datos por animal'!O84 -> 42.2 | F8: ='Datos por animal'!O104 -> 101.3
A9: ='Datos por animal'!O8 -> 25.3 | B9: ='Datos por animal'!O27 -> 39.7 | C9: ='Datos por animal'!O45 -> 34.9 | D9: ='Datos por animal'!O65 -> 67.9 | E9: ='Datos por animal'!O85 -> 24.3 | F9: ='Datos por animal'!O105 -> 57.2
A10: ='Datos por animal'!O9 -> 33.8 | B10: ='Datos por animal'!O28 -> 51.6 | C10: ='Datos por animal'!O46 -> 29.5 | D10: ='Datos por animal'!O66 -> 72.1 | E10: ='Datos por animal'!O86 -> 38.3 | F10: ='Datos por animal'!O106 -> 60.3
A11: ='Datos por animal'!O10 -> 30.6 | B11: ='Datos por animal'!O29 -> 60.5 | C11: ='Datos por animal'!O47 -> 70 | D11: ='Datos por animal'!O67 -> 38 | E11: ='Datos por animal'!O87 -> 26.9 | F11: ='Datos por animal'!O107 -> 30.3
A12: ='Datos por animal'!O11 -> 31.1 | B12: ='Datos por animal'!O30 -> 56.9 | C12: ='Datos por animal'!O48 -> 73.4 | D12: ='Datos por animal'!O68 -> 54.3 | E12: ='Datos por animal'!O88 -> 38 | F12: ='Datos por animal'!O108 -> 34.8
A13: ='Datos por animal'!O12 -> 6.6 | B13: ='Datos por animal'!O31 -> 30.9 | C13: ='Datos por animal'!O49 -> 96.4 | D13: ='Datos por animal'!O69 -> 25.9 | E13: ='Datos por animal'!O89 -> 35.5 | F13: ='Datos por animal'!O109 -> 35.4
A14: ='Datos por animal'!O13 -> 21.5 | B14: ='Datos por animal'!O32 -> 21.5 | C14: ='Datos por animal'!O50 -> 26.9 | D14: ='Datos por animal'!O70 -> 23.9 | E14: ='Datos por animal'!O90 -> 55.9 | F14: ='Datos por animal'!O110 -> 26.2
C15: ='Datos por animal'!O51 -> 37 | D15: ='Datos por animal'!O71 -> 18.1 | E15: ='Datos por animal'!O91 -> 39.1 | F15: ='Datos por animal'!O111 -> 84.4
A18: Exploración total D1 (s) – s-SLR (isósceles)
A19: Juvenil – Control | B19: Juvenil – Sacarosa | C19: Juvenil – Stevia | D19: Adulto – Control | E19: Adulto – Sacarosa | F19: Adulto – Stevia
A20: ='Datos por animal'!O14 -> 37.6 | B20: ='Datos por animal'!O33 -> 71.2 | C20: ='Datos por animal'!O52 -> 28.3 | D20: ='Datos por animal'!O72 -> 37.9 | E20: ='Datos por animal'!O92 -> 34.6 | F20: ='Datos por animal'!O112 -> 56.2
A21: ='Datos por animal'!O15 -> 36.5 | B21: ='Datos por animal'!O34 -> 43.1 | C21: ='Datos por animal'!O53 -> 50.2 | D21: ='Datos por animal'!O73 -> 44.4 | E21: ='Datos por animal'!O93 -> 27.1 | F21: ='Datos por animal'!O113 -> 74.8
A22: ='Datos por animal'!O16 -> 22.8 | B22: ='Datos por animal'!O35 -> 63.1 | C22: ='Datos por animal'!O54 -> 36.5 | D22: ='Datos por animal'!O74 -> 30.1 | E22: ='Datos por animal'!O94 -> 53 | F22: ='Datos por animal'!O114 -> 99.7
A23: ='Datos por animal'!O17 -> 35.3 | B23: ='Datos por animal'!O36 -> 59.4 | C23: ='Datos por animal'!O55 -> 28 | D23: ='Datos por animal'!O75 -> 26 | E23: ='Datos por animal'!O95 -> 34.8 | F23: ='Datos por animal'!O115 -> 79.1
A24: ='Datos por animal'!O18 -> 28.9 | B24: ='Datos por animal'!O37 -> 52.5 | C24: ='Datos por animal'!O56 -> 22.7 | D24: ='Datos por animal'!O76 -> 35.7 | E24: ='Datos por animal'!O96 -> 26.1 | F24: ='Datos por animal'!O116 -> 50.5
A25: ='Datos por animal'!O19 -> 49.3 | B25: ='Datos por animal'!O38 -> 43.5 | C25: ='Datos por animal'!O57 -> 16.4 | D25: ='Datos por animal'!O77 -> 17.9 | E25: ='Datos por animal'!O97 -> 33.5 | F25: ='Datos por animal'!O117 -> 29.6
A26: ='Datos por animal'!O20 -> 31.2 | B26: ='Datos por animal'!O39 -> 46.8 | C26: ='Datos por animal'!O58 -> 17.5 | D26: ='Datos por animal'!O78 -> 16.1 | E26: ='Datos por animal'!O98 -> 31.3 | F26: ='Datos por animal'!O118 -> 42.8
A27: ='Datos por animal'!O21 -> 26 | B27: ='Datos por animal'!O40 -> 74.5 | C27: ='Datos por animal'!O59 -> 64.4 | D27: ='Datos por animal'!O79 -> 20.9 | E27: ='Datos por animal'!O99 -> 50.8 | F27: ='Datos por animal'!O119 -> 24.7
A28: ='Datos por animal'!O22 -> 26.6 | B28: ='Datos por animal'!O41 -> 69.9 | C28: ='Datos por animal'!O60 -> 52.4 | D28: ='Datos por animal'!O80 -> 27.1 | E28: ='Datos por animal'!O100 -> 44.4 | F28: ='Datos por animal'!O120 -> 27.7
A29: ='Datos por animal'!O23 -> 11.8 | C29: ='Datos por animal'!O61 -> 83.2 | D29: ='Datos por animal'!O81 -> 49.3 | E29: ='Datos por animal'!O101 -> 42.1 | F29: ='Datos por animal'!O121 -> 69.3
A32: % tiempo en objeto fijo (azar 33,3 %) – d-SLR (equilátero)
A33: Juvenil – Control | B33: Juvenil – Sacarosa | C33: Juvenil – Stevia | D33: Adulto – Control | E33: Adulto – Sacarosa | F33: Adulto – Stevia
A34: ='Datos por animal'!P5 -> 0.18859649 | B34: ='Datos por animal'!P24 -> 0.2557652 | C34: ='Datos por animal'!P42 -> 0.22368421 | D34: ='Datos por animal'!P62 -> 0.27346939 | E34: ='Datos por animal'!P82 -> 0.42253521 | F34: ='Datos por animal'!P102 -> 0.36128237
A35: ='Datos por animal'!P6 -> 0.19889503 | B35: ='Datos por animal'!P25 -> 0.43298969 | C35: ='Datos por animal'!P43 -> 0.38421053 | D35: ='Datos por animal'!P63 -> 0.58690745 | E35: ='Datos por animal'!P83 -> 0.20689655 | F35: ='Datos por animal'!P103 -> 0.26156942
A36: ='Datos por animal'!P7 -> 0.26765799 | B36: ='Datos por animal'!P26 -> 0.39087019 | C36: ='Datos por animal'!P44 -> 0.16803279 | D36: ='Datos por animal'!P64 -> 0.52006689 | E36: ='Datos por animal'!P84 -> 0.12322275 | F36: ='Datos por animal'!P104 -> 0.24975321
A37: ='Datos por animal'!P8 -> 0.50988142 | B37: ='Datos por animal'!P27 -> 0.4231738 | C37: ='Datos por animal'!P45 -> 0.38681948 | D37: ='Datos por animal'!P65 -> 0.28129602 | E37: ='Datos por animal'!P85 -> 0.49382716 | F37: ='Datos por animal'!P105 -> 0.44230769
A38: ='Datos por animal'!P9 -> 0.37869822 | B38: ='Datos por animal'!P28 -> 0.37790698 | C38: ='Datos por animal'!P46 -> 0.3559322 | D38: ='Datos por animal'!P66 -> 0.30097087 | E38: ='Datos por animal'!P86 -> 0.4073107 | F38: ='Datos por animal'!P106 -> 0.28855721
A39: ='Datos por animal'!P10 -> 0.15686275 | B39: ='Datos por animal'!P29 -> 0.3553719 | C39: ='Datos por animal'!P47 -> 0.28285714 | D39: ='Datos por animal'!P67 -> 0.33421053 | E39: ='Datos por animal'!P87 -> 0.40892193 | F39: ='Datos por animal'!P107 -> 0.41254125
A40: ='Datos por animal'!P11 -> 0.42765273 | B40: ='Datos por animal'!P30 -> 0.26889279 | C40: ='Datos por animal'!P48 -> 0.47411444 | D40: ='Datos por animal'!P68 -> 0.55064457 | E40: ='Datos por animal'!P88 -> 0.52368421 | F40: ='Datos por animal'!P108 -> 0.63505747
A41: ='Datos por animal'!P12 -> 0.51515152 | B41: ='Datos por animal'!P31 -> 0.40776699 | C41: ='Datos por animal'!P49 -> 0.45435685 | D41: ='Datos por animal'!P69 -> 0.29343629 | E41: ='Datos por animal'!P89 -> 0.23380282 | F41: ='Datos por animal'!P109 -> 0.44067797
A42: ='Datos por animal'!P13 -> 0.22325581 | B42: ='Datos por animal'!P32 -> 0.093023256 | C42: ='Datos por animal'!P50 -> 0.2936803 | D42: ='Datos por animal'!P70 -> 0.30125523 | E42: ='Datos por animal'!P90 -> 0.37030411 | F42: ='Datos por animal'!P110 -> 0.14885496
C43: ='Datos por animal'!P51 -> 0.39189189 | D43: ='Datos por animal'!P71 -> 0.22651934 | E43: ='Datos por animal'!P91 -> 0.48081841 | F43: ='Datos por animal'!P111 -> 0.1563981
A46: % tiempo en objeto fijo (azar 33,3 %) – s-SLR (isósceles)
A47: Juvenil – Control | B47: Juvenil – Sacarosa | C47: Juvenil – Stevia | D47: Adulto – Control | E47: Adulto – Sacarosa | F47: Adulto – Stevia
...
