Workbook

Sheet Resumen D1
A1: SLR – Día 1 (muestreo): exploración, preferencia de posición y distancia recorrida por grupo
A3: Qué es | B3: Control de la fase de codificación. El día 1 hay tres objetos idénticos y ninguno es novedoso, así que no se calcula DI: se verifica que los grupos hayan explorado de forma comparable y sin preferencia previa por una posición.
A4: Exploración total D1 | B4: Suma del tiempo explorando los tres objetos (s). Todas las sesiones del día 1 duran 10 min, así que es comparable entre grupos (no con el día 2, que dura 5 min y tiene 2 objetos).
A5: % en objeto fijo | B5: Tiempo en el objeto que queda en su lugar en el test (será el familiar) / exploración total. Azar = 33,3 %. Valores por encima indican que el grupo ya prefería esa posición antes del test.
A6: Distancia D1 | B6: Distancia recorrida en la sesión (tracking automático de AnyMaze©), como medida de actividad locomotora. También se da por minuto para corregir las sesiones cortadas antes de los 10 min.
A7: n | B7: Animales por grupo y configuración (cada animal aparece una vez por configuración), igual que en el análisis del día 2.
A9: Grupo | B9: d-SLR (equilátero) | E9: s-SLR (isósceles)
B10: n | C10: Exploración total (s) | D10: % en objeto fijo | E10: n | F10: Exploración total (s) | G10: % en objeto fijo
A11: Juvenil – Control | B11: =COUNTIFS('Datos por animal'!$C:$C,$A11,'Datos por animal'!$D:$D,"d-SLR (equilátero)") -> 9 | C11: =AVERAGEIFS('Datos por animal'!$O:$O,'Datos por animal'!$C:$C,$A11,'Datos por animal'!$D:$D,"d-SLR (equilátero)") -> 30.633333 | D11: =AVERAGEIFS('Datos por animal'!$P:$P,'Datos por animal'!$C:$C,$A11,'Datos por animal'!$D:$D,"d-SLR (equilátero)") -> 0.31851689 | E11: =COUNTIFS('Datos por animal'!$C:$C,$A11,'Datos por animal'!$D:$D,"s-SLR (isósceles)") -> 10 | F11: =AVERAGEIFS('Datos por animal'!$O:$O,'Datos por animal'!$C:$C,$A11,'Datos por animal'!$D:$D,"s-SLR (isósceles)") -> 30.6 | G11: =AVERAGEIFS('Datos por animal'!$P:$P,'Datos por animal'!$C:$C,$A11,'Datos por animal'!$D:$D,"s-SLR (isósceles)") -> 0.33009801
A12: Juvenil – Sacarosa | B12: =COUNTIFS('Datos por animal'!$C:$C,$A12,'Datos por animal'!$D:$D,"d-SLR (equilátero)") -> 9 | C12: =AVERAGEIFS('Datos por animal'!$O:$O,'Datos por animal'!$C:$C,$A12,'Datos por animal'!$D:$D,"d-SLR (equilátero)") -> 50.722222 | D12: =AVERAGEIFS('Datos por animal'!$P:$P,'Datos por animal'!$C:$C,$A12,'Datos por animal'!$D:$D,"d-SLR (equilátero)") -> 0.33397342 | E12: =COUNTIFS('Datos por animal'!$C:$C,$A12,'Datos por animal'!$D:$D,"s-SLR (isósceles)") -> 9 | F12: =AVERAGEIFS('Datos por animal'!$O:$O,'Datos por animal'!$C:$C,$A12,'Datos por animal'!$D:$D,"s-SLR (isósceles)") -> 58.222222 | G12: =AVERAGEIFS('Datos por animal'!$P:$P,'Datos por animal'!$C:$C,$A12,'Datos por animal'!$D:$D,"s-SLR (isósceles)") -> 0.35415745
A13: Juvenil – Stevia | B13: =COUNTIFS('Datos por animal'!$C:$C,$A13,'Datos por animal'!$D:$D,"d-SLR (equilátero)") -> 10 | C13: =AVERAGEIFS('Datos por animal'!$O:$O,'Datos por animal'!$C:$C,$A13,'Datos por animal'!$D:$D,"d-SLR (equilátero)") -> 43.43 | D13: =AVERAGEIFS('Datos por animal'!$P:$P,'Datos por animal'!$C:$C,$A13,'Datos por animal'!$D:$D,"d-SLR (equilátero)") -> 0.34155798 | E13: =COUNTIFS('Datos por animal'!$C:$C,$A13,'Datos por animal'!$D:$D,"s-SLR (isósceles)") -> 10 | F13: =AVERAGEIFS('Datos por animal'!$O:$O,'Datos por animal'!$C:$C,$A13,'Datos por animal'!$D:$D,"s-SLR (isósceles)") -> 39.96 | G13: =AVERAGEIFS('Datos por animal'!$P:$P,'Datos por animal'!$C:$C,$A13,'Datos por animal'!$D:$D,"s-SLR (isósceles)") -> 0.3947219
A14: Adulto – Control | B14: =COUNTIFS('Datos por animal'!$C:$C,$A14,'Datos por animal'!$D:$D,"d-SLR (equilátero)") -> 10 | C14: =AVERAGEIFS('Datos por animal'!$O:$O,'Datos por animal'!$C:$C,$A14,'Datos por animal'!$D:$D,"d-SLR (equilátero)") -> 42.88 | D14: =AVERAGEIFS('Datos por animal'!$P:$P,'Datos por animal'!$C:$C,$A14,'Datos por animal'!$D:$D,"d-SLR (equilátero)") -> 0.36687766 | E14: =COUNTIFS('Datos por animal'!$C:$C,$A14,'Datos por animal'!$D:$D,"s-SLR (isósceles)") -> 10 | F14: =AVERAGEIFS('Datos por animal'!$O:$O,'Datos por animal'!$C:$C,$A14,'Datos por animal'!$D:$D,"s-SLR (isósceles)") -> 30.54 | G14: =AVERAGEIFS('Datos por animal'!$P:$P,'Datos por animal'!$C:$C,$A14,'Datos por animal'!$D:$D,"s-SLR (isósceles)") -> 0.45126399
A15: Adulto – Sacarosa | B15: =COUNTIFS('Datos por animal'!$C:$C,$A15,'Datos por animal'!$D:$D,"d-SLR (equilátero)") -> 10 | C15: =AVERAGEIFS('Datos por animal'!$O:$O,'Datos por animal'!$C:$C,$A15,'Datos por animal'!$D:$D,"d-SLR (equilátero)") -> 37.18 | D15: =AVERAGEIFS('Datos por animal'!$P:$P,'Datos por animal'!$C:$C,$A15,'Datos por animal'!$D:$D,"d-SLR (equilátero)") -> 0.36713239 | E15: =COUNTIFS('Datos por animal'!$C:$C,$A15,'Datos por animal'!$D:$D,"s-SLR (isósceles)") -> 10 | F15: =AVERAGEIFS('Datos por animal'!$O:$O,'Datos por animal'!$C:$C,$A15,'Datos por animal'!$D:$D,"s-SLR (isósceles)") -> 37.77 | G15: =AVERAGEIFS('Datos por animal'!$P:$P,'Datos por animal'!$C:$C,$A15,'Datos por animal'!$D:$D,"s-SLR (isósceles)") -> 0.4779685
A16: Adulto – Stevia | B16: =COUNTIFS('Datos por animal'!$C:$C,$A16,'Datos por animal'!$D:$D,"d-SLR (equilátero)") -> 10 | C16: =AVERAGEIFS('Datos por animal'!$O:$O,'Datos por animal'!$C:$C,$A16,'Datos por animal'!$D:$D,"d-SLR (equilátero)") -> 56.07 | D16: =AVERAGEIFS('Datos por animal'!$P:$P,'Datos por animal'!$C:$C,$A16,'Datos por animal'!$D:$D,"d-SLR (equilátero)") -> 0.33969997 | E16: =COUNTIFS('Datos por animal'!$C:$C,$A16,'Datos por animal'!$D:$D,"s-SLR (isósceles)") -> 10 | F16: =AVERAGEIFS('Datos por animal'!$O:$O,'Datos por animal'!$C:$C,$A16,'Datos por animal'!$D:$D,"s-SLR (isósceles)") -> 55.44 | G16: =AVERAGEIFS('Datos por animal'!$P:$P,'Datos por animal'!$C:$C,$A16,'Datos por animal'!$D:$D,"s-SLR (isósceles)") -> 0.38003845
A18: Distancia recorrida D1
A19: Grupo | B19: d-SLR (equilátero) | E19: s-SLR (isósceles)
B20: n | C20: Distancia (m) | D20: m/min | E20: n | F20: Distancia (m) | G20: m/min
A21: Juvenil – Control | B21: =COUNTIFS('Datos por animal'!$C:$C,$A21,'Datos por animal'!$D:$D,"d-SLR (equilátero)",'Datos por animal'!$Q:$Q,">0") -> 6 | C21: =AVERAGEIFS('Datos por animal'!$Q:$Q,'Datos por animal'!$C:$C,$A21,'Datos por animal'!$D:$D,"d-SLR (equilátero)") -> 38.540167 | D21: =AVERAGEIFS('Datos por animal'!$R:$R,'Datos por animal'!$C:$C,$A21,'Datos por animal'!$D:$D,"d-SLR (equilátero)") -> 3.8665685 | E21: =COUNTIFS('Datos por animal'!$C:$C,$A21,'Datos por animal'!$D:$D,"s-SLR (isósceles)",'Datos por animal'!$Q:$Q,">0") -> 8 | F21: =AVERAGEIFS('Datos por animal'!$Q:$Q,'Datos por animal'!$C:$C,$A21,'Datos por animal'!$D:$D,"s-SLR (isósceles)") -> 35.23075 | G21: =AVERAGEIFS('Datos por animal'!$R:$R,'Datos por animal'!$C:$C,$A21,'Datos por animal'!$D:$D,"s-SLR (isósceles)") -> 3.5856878
A22: Juvenil – Sacarosa | B22: =COUNTIFS('Datos por animal'!$C:$C,$A22,'Datos por animal'!$D:$D,"d-SLR (equilátero)",'Datos por animal'!$Q:$Q,">0") -> 9 | C22: =AVERAGEIFS('Datos por animal'!$Q:$Q,'Datos por animal'!$C:$C,$A22,'Datos por animal'!$D:$D,"d-SLR (equilátero)") -> 52.040333 | D22: =AVERAGEIFS('Datos por animal'!$R:$R,'Datos por animal'!$C:$C,$A22,'Datos por animal'!$D:$D,"d-SLR (equilátero)") -> 5.2156493 | E22: =COUNTIFS('Datos por animal'!$C:$C,$A22,'Datos por animal'!$D:$D,"s-SLR (isósceles)",'Datos por animal'!$Q:$Q,">0") -> 9 | F22: =AVERAGEIFS('Datos por animal'!$Q:$Q,'Datos por animal'!$C:$C,$A22,'Datos por animal'!$D:$D,"s-SLR (isósceles)") -> 53.568222 | G22: =AVERAGEIFS('Datos por animal'!$R:$R,'Datos por animal'!$C:$C,$A22,'Datos por animal'!$D:$D,"s-SLR (isósceles)") -> 5.3636853
A23: Juvenil – Stevia | B23: =COUNTIFS('Datos por animal'!$C:$C,$A23,'Datos por animal'!$D:$D,"d-SLR (equilátero)",'Datos por animal'!$Q:$Q,">0") -> 10 | C23: =AVERAGEIFS('Datos por animal'!$Q:$Q,'Datos por animal'!$C:$C,$A23,'Datos por animal'!$D:$D,"d-SLR (equilátero)") -> 46.7159 | D23: =AVERAGEIFS('Datos por animal'!$R:$R,'Datos por animal'!$C:$C,$A23,'Datos por animal'!$D:$D,"d-SLR (equilátero)") -> 4.6825678 | E23: =COUNTIFS('Datos por animal'!$C:$C,$A23,'Datos por animal'!$D:$D,"s-SLR (isósceles)",'Datos por animal'!$Q:$Q,">0") -> 10 | F23: =AVERAGEIFS('Datos por animal'!$Q:$Q,'Datos por animal'!$C:$C,$A23,'Datos por animal'!$D:$D,"s-SLR (isósceles)") -> 49.7304 | G23: =AVERAGEIFS('Datos por animal'!$R:$R,'Datos por animal'!$C:$C,$A23,'Datos por animal'!$D:$D,"s-SLR (isósceles)") -> 5.0237425
A24: Adulto – Control | B24: =COUNTIFS('Datos por animal'!$C:$C,$A24,'Datos por animal'!$D:$D,"d-SLR (equilátero)",'Datos por animal'!$Q:$Q,">0") -> 9 | C24: =AVERAGEIFS('Datos por animal'!$Q:$Q,'Datos por animal'!$C:$C,$A24,'Datos por animal'!$D:$D,"d-SLR (equilátero)") -> 29.842 | D24: =AVERAGEIFS('Datos por animal'!$R:$R,'Datos por animal'!$C:$C,$A24,'Datos por animal'!$D:$D,"d-SLR (equilátero)") -> 3.1387801 | E24: =COUNTIFS('Datos por animal'!$C:$C,$A24,'Datos por animal'!$D:$D,"s-SLR (isósceles)",'Datos por animal'!$Q:$Q,">0") -> 10 | F24: =AVERAGEIFS('Datos por animal'!$Q:$Q,'Datos por animal'!$C:$C,$A24,'Datos por animal'!$D:$D,"s-SLR (isósceles)") -> 26.2103 | G24: =AVERAGEIFS('Datos por animal'!$R:$R,'Datos por animal'!$C:$C,$A24,'Datos por animal'!$D:$D,"s-SLR (isósceles)") -> 2.62103
A25: Adulto – Sacarosa | B25: =COUNTIFS('Datos por animal'!$C:$C,$A25,'Datos por animal'!$D:$D,"d-SLR (equilátero)",'Datos por animal'!$Q:$Q,">0") -> 10 | C25: =AVERAGEIFS('Datos por animal'!$Q:$Q,'Datos por animal'!$C:$C,$A25,'Datos por animal'!$D:$D,"d-SLR (equilátero)") -> 45.7707 | D25: =AVERAGEIFS('Datos por animal'!$R:$R,'Datos por animal'!$C:$C,$A25,'Datos por animal'!$D:$D,"d-SLR (equilátero)") -> 4.651317 | E25: =COUNTIFS('Datos por animal'!$C:$C,$A25,'Datos por animal'!$D:$D,"s-SLR (isósceles)",'Datos por animal'!$Q:$Q,">0") -> 10 | F25: =AVERAGEIFS('Datos por animal'!$Q:$Q,'Datos por animal'!$C:$C,$A25,'Datos por animal'!$D:$D,"s-SLR (isósceles)") -> 44.7756 | G25: =AVERAGEIFS('Datos por animal'!$R:$R,'Datos por animal'!$C:$C,$A25,'Datos por animal'!$D:$D,"s-SLR (isósceles)") -> 4.4804856
A26: Adulto – Stevia | B26: =COUNTIFS('Datos por animal'!$C:$C,$A26,'Datos por animal'!$D:$D,"d-SLR (equilátero)",'Datos por animal'!$Q:$Q,">0") -> 10 | C26: =AVERAGEIFS('Datos por animal'!$Q:$Q,'Datos por animal'!$C:$C,$A26,'Datos por animal'!$D:$D,"d-SLR (equilátero)") -> 41.0645 | D26: =AVERAGEIFS('Datos por animal'!$R:$R,'Datos por animal'!$C:$C,$A26,'Datos por animal'!$D:$D,"d-SLR (equilátero)") -> 4.1246276 | E26: =COUNTIFS('Datos por animal'!$C:$C,$A26,'Datos por animal'!$D:$D,"s-SLR (isósceles)",'Datos por animal'!$Q:$Q,">0") -> 10 | F26: =AVERAGEIFS('Datos por animal'!$Q:$Q,'Datos por animal'!$C:$C,$A26,'Datos por animal'!$D:$D,"s-SLR (isósceles)") -> 44.4574 | G26: =AVERAGEIFS('Datos por animal'!$R:$R,'Datos por animal'!$C:$C,$A26,'Datos por animal'!$D:$D,"s-SLR (isósceles)") -> 4.44574
A28: Distancia recorrida D1 por lote / cohorte (ambas configuraciones)
A29: Lote / cohorte | B29: Edad | C29: n sesiones | D29: Distancia (m) | E29: m/min
A30: Sac/Stevia 2026 par 1 | B30: Juvenil | C30: =COUNTIFS('Datos por animal'!$E:$E,$A30,'Datos por animal'!$A:$A,$B30,'Datos por animal'!$Q:$Q,">0") -> 10 | D30: =IFERROR(AVERAGEIFS('Datos por animal'!$Q:$Q,'Datos por animal'!$E:$E,$A30,'Datos por animal'!$A:$A,$B30),"sin dato") -> 54.067 | E30: =IFERROR(AVERAGEIFS('Datos por animal'!$R:$R,'Datos por animal'!$E:$E,$A30,'Datos por animal'!$A:$A,$B30),"sin dato") -> 5.4180175
A31: Sac/Stevia 2026 par 2 | B31: Juvenil | C31: =COUNTIFS('Datos por animal'!$E:$E,$A31,'Datos por animal'!$A:$A,$B31,'Datos por animal'!$Q:$Q,">0") -> 10 | D31: =IFERROR(AVERAGEIFS('Datos por animal'!$Q:$Q,'Datos por animal'!$E:$E,$A31,'Datos por animal'!$A:$A,$B31),"sin dato") -> 62.5382 | E31: =IFERROR(AVERAGEIFS('Datos por animal'!$R:$R,'Datos por animal'!$E:$E,$A31,'Datos por animal'!$A:$A,$B31),"sin dato") -> 6.25382
A32: Control oct 2025 | B32: Juvenil | C32: =COUNTIFS('Datos por animal'!$E:$E,$A32,'Datos por animal'!$A:$A,$B32,'Datos por animal'!$Q:$Q,">0") -> 5 | D32: =IFERROR(AVERAGEIFS('Datos por animal'!$Q:$Q,'Datos por animal'!$E:$E,$A32,'Datos por animal'!$A:$A,$B32),"sin dato") -> 33.2352 | E32: =IFERROR(AVERAGEIFS('Datos por animal'!$R:$R,'Datos por animal'!$E:$E,$A32,'Datos por animal'!$A:$A,$B32),"sin dato") -> 3.4006953
A33: Ctrl/Stevia jun 2025 | B33: Juvenil | C33: =COUNTIFS('Datos por animal'!$E:$E,$A33,'Datos por animal'!$A:$A,$B33,'Datos por animal'!$Q:$Q,">0") -> 19 | D33: =IFERROR(AVERAGEIFS('Datos por animal'!$Q:$Q,'Datos por animal'!$E:$E,$A33,'Datos por animal'!$A:$A,$B33),"sin dato") -> 39.924 | E33: =IFERROR(AVERAGEIFS('Datos por animal'!$R:$R,'Datos por animal'!$E:$E,$A33,'Datos por animal'!$A:$A,$B33),"sin dato") -> 4.0331193
A34: Sacarosa jun 2025 | B34: Juvenil | C34: =COUNTIFS('Datos por animal'!$E:$E,$A34,'Datos por animal'!$A:$A,$B34,'Datos por animal'!$Q:$Q,">0") -> 8 | D34: =IFERROR(AVERAGEIFS('Datos por animal'!$Q:$Q,'Datos por animal'!$E:$E,$A34,'Datos por animal'!$A:$A,$B34),"sin dato") -> 42.155375 | E34: =IFERROR(AVERAGEIFS('Datos por animal'!$R:$R,'Datos por animal'!$E:$E,$A34,'Datos por animal'!$A:$A,$B34),"sin dato") -> 4.2263636
A35: Stevia 2024 | B35: Adulto | C35: =COUNTIFS('Datos por animal'!$E:$E,$A35,'Datos por animal'!$A:$A,$B35,'Datos por animal'!$Q:$Q,">0") -> 10 | D35: =IFERROR(AVERAGEIFS('Datos por animal'!$Q:$Q,'Datos por animal'!$E:$E,$A35,'Datos por animal'!$A:$A,$B35),"sin dato") -> 37.5854 | E35: =IFERROR(AVERAGEIFS('Datos por animal'!$R:$R,'Datos por animal'!$E:$E,$A35,'Datos por animal'!$A:$A,$B35),"sin dato") -> 3.75854
A36: Control dic 2025 | B36: Adulto | C36: =COUNTIFS('Datos por animal'!$E:$E,$A36,'Datos por animal'!$A:$A,$B36,'Datos por animal'!$Q:$Q,">0") -> 10 | D36: =IFERROR(AVERAGEIFS('Datos por animal'!$Q:$Q,'Datos por animal'!$E:$E,$A36,'Datos por animal'!$A:$A,$B36),"sin dato") -> 31.7499 | E36: =IFERROR(AVERAGEIFS('Datos por animal'!$R:$R,'Datos por animal'!$E:$E,$A36,'Datos por animal'!$A:$A,$B36),"sin dato") -> 3.17499
A37: Ctrl/Sac mayo 2025 | B37: Adulto | C37: =COUNTIFS('Datos por animal'!$E:$E,$A37,'Datos por animal'!$A:$A,$B37,'Datos por animal'!$Q:$Q,">0") -> 19 | D37: =IFERROR(AVERAGEIFS('Datos por animal'!$Q:$Q,'Datos por animal'!$E:$E,$A37,'Datos por animal'!$A:$A,$B37),"sin dato") -> 27.055211 | E37: =IFERROR(AVERAGEIFS('Datos por animal'!$R:$R,'Datos por animal'!$E:$E,$A37,'Datos por animal'!$A:$A,$B37),"sin dato") -> 2.8126284
A38: Sac/Stevia 2026 | B38: Adulto | C38: =COUNTIFS('Datos por animal'!$E:$E,$A38,'Datos por animal'!$A:$A,$B38,'Datos por animal'!$Q:$Q,">0") -> 20 | D38: =IFERROR(AVERAGEIFS('Datos por animal'!$Q:$Q,'Datos por animal'!$E:$E,$A38,'Datos por animal'!$A:$A,$B38),"sin dato") -> 54.19805 | E38: =IFERROR(AVERAGEIFS('Datos por animal'!$R:$R,'Datos por animal'!$E:$E,$A38,'Datos por animal'!$A:$A,$B38),"sin dato") -> 5.4352892
A40: Valores: media del grupo (sin SEM ni estadística). Datos individuales en "Datos por animal"; columnas listas para pegar en Prism en la pestaña "Prism".
A41: Asignación de grupos: Juvenil – Control incluye los lotes de junio y octubre 2025; Adulto – Control, mayo y diciembre 2025; Sacarosa y Stevia incluyen las cohortes 2024/2025 y 2026.
A42: Objeto fijo asumido (no anotado en la hoja original): Zona 2 en la tanda equilátero del 08/05/2025; Zona 1 en equilátero de adultos 2026 y del par 1 juvenil 2026. A confirmar.
A43: Hay 8 sesiones de menos de ~10 min (cortes anticipados del registro, de 402 a 589 s) y 5 sin dato de duración (control juvenil oct 2025, vasos), marcadas en "Datos por animal"; no se excluyeron.
A44: Excluido 1 registro duplicado: "con 1 raya" (repetición del muestreo de con 1, adulto mayo 2025).
A45: Distancia sin dato: con 1 (adulto mayo 2025, falló el tracking) y lote control juvenil oct 2025 con vasos (no registrada); el n de distancia es menor en esos grupos.
...

Sheet Datos por animal
A1: SLR – Día 1 (muestreo, 3 objetos idénticos) – datos por animal
A2: Una fila por animal y configuración. Columnas L–N: tiempo de exploración manual (time pressed de AnyMaze©) de cada objeto. Celdas amarillas = fórmulas. Sin exclusiones por umbral; valores tal cual del registro.
A4: Edad | B4: Tratamiento | C4: Grupo | D4: Configuración | E4: Lote / cohorte | F4: Objetos | G4: Fecha D1 | H4: Pestaña de origen | I4: Animal (etiqueta original) | J4: Duración sesión (s) | K4: Zona del objeto fijo | L4: t objeto fijo (s) (queda en el test) | M4: t objeto desplazado 1 (s) | N4: t objeto desplazado 2 (s) | O4: Exploración total D1 (s) | P4: % tiempo en objeto fijo | Q4: Distancia recorrida D1 (m) | R4: Distancia por minuto (m/min) | S4: Zonas de los objetos desplazados
A5: Juvenil | B5: Control | C5: Juvenil – Control | D5: d-SLR (equilátero) | E5: Ctrl/Stevia jun 2025 | F5: — | G5: 05/06/2025 | H5: 250605 D1 Ctrl+Stevia | I5: CON 1 | J5: 598.8 | K5: Zona 1 | L5: 8.6 | M5: 17.8 | N5: 19.2 | O5: =L5+M5+N5 -> 45.6 | P5: =IF(O5=0,"",L5/O5) -> 0.18859649 | Q5: 51.322 | R5: =IF(AND(ISNUMBER(Q5),ISNUMBER(J5)),Q5/(J5/60),"") -> 5.142485 | S5: Zona 2 / Zona 3
A6: Juvenil | B6: Control | C6: Juvenil – Control | D6: d-SLR (equilátero) | E6: Ctrl/Stevia jun 2025 | F6: — | G6: 05/06/2025 | H6: 250605 D1 Ctrl+Stevia | I6: CON 2 | J6: 592.7 | K6: Zona 1 | L6: 10.8 | M6: 22.5 | N6: 21 | O6: =L6+M6+N6 -> 54.3 | P6: =IF(O6=0,"",L6/O6) -> 0.19889503 | Q6: 44.794 | R6: =IF(AND(ISNUMBER(Q6),ISNUMBER(J6)),Q6/(J6/60),"") -> 4.5345706 | S6: Zona 2 / Zona 3
A7: Juvenil | B7: Control | C7: Juvenil – Control | D7: d-SLR (equilátero) | E7: Ctrl/Stevia jun 2025 | F7: — | G7: 05/06/2025 | H7: 250605 D1 Ctrl+Stevia | I7: CON 3 | J7: 600 | K7: Zona 1 | L7: 7.2 | M7: 10.3 | N7: 9.4 | O7: =L7+M7+N7 -> 26.9 | P7: =IF(O7=0,"",L7/O7) -> 0.26765799 | Q7: 23.543 | R7: =IF(AND(ISNUMBER(Q7),ISNUMBER(J7)),Q7/(J7/60),"") -> 2.3543 | S7: Zona 2 / Zona 3
A8: Juvenil | B8: Control | C8: Juvenil – Control | D8: d-SLR (equilátero) | E8: Ctrl/Stevia jun 2025 | F8: — | G8: 05/06/2025 | H8: 250605 D1 Ctrl+Stevia | I8: CON 4 | J8: 598.8 | K8: Zona 1 | L8: 12.9 | M8: 4.8 | N8: 7.6 | O8: =L8+M8+N8 -> 25.3 | P8: =IF(O8=0,"",L8/O8) -> 0.50988142 | Q8: 49.178 | R8: =IF(AND(ISNUMBER(Q8),ISNUMBER(J8)),Q8/(J8/60),"") -> 4.9276553 | S8: Zona 2 / Zona 3
A9: Juvenil | B9: Control | C9: Juvenil – Control | D9: d-SLR (equilátero) | E9: Control oct 2025 | F9: Vasos | G9: 30/10/2025 | H9: 251030 D1 Ctrl-oct vasos | I9: 1 | J9: sin dato | K9: Zona 1 | L9: 12.8 | M9: 11.4 | N9: 9.6 | O9: =L9+M9+N9 -> 33.8 | P9: =IF(O9=0,"",L9/O9) -> 0.37869822 | Q9: sin dato | R9: =IF(AND(ISNUMBER(Q9),ISNUMBER(J9)),Q9/(J9/60),"") | S9: Zona 2 / Zona 3
A10: Juvenil | B10: Control | C10: Juvenil – Control | D10: d-SLR (equilátero) | E10: Control oct 2025 | F10: Vasos | G10: 30/10/2025 | H10: 251030 D1 Ctrl-oct vasos | I10: 2 | J10: sin dato | K10: Zona 1 | L10: 4.8 | M10: 10.7 | N10: 15.1 | O10: =L10+M10+N10 -> 30.6 | P10: =IF(O10=0,"",L10/O10) -> 0.15686275 | Q10: sin dato | R10: =IF(AND(ISNUMBER(Q10),ISNUMBER(J10)),Q10/(J10/60),"") | S10: Zona 2 / Zona 3
A11: Juvenil | B11: Control | C11: Juvenil – Control | D11: d-SLR (equilátero) | E11: Control oct 2025 | F11: Vasos | G11: 30/10/2025 | H11: 251030 D1 Ctrl-oct vasos | I11: 3 | J11: sin dato | K11: Zona 1 | L11: 13.3 | M11: 12.4 | N11: 5.4 | O11: =L11+M11+N11 -> 31.1 | P11: =IF(O11=0,"",L11/O11) -> 0.42765273 | Q11: sin dato | R11: =IF(AND(ISNUMBER(Q11),ISNUMBER(J11)),Q11/(J11/60),"") | S11: Zona 2 / Zona 3
A12: Juvenil | B12: Control | C12: Juvenil – Control | D12: d-SLR (equilátero) | E12: Control oct 2025 | F12: Ranas | G12: 03/11/2025 | H12: 251103 D1 Ctrl-oct ranas | I12: 4 | J12: 600 | K12: Zona 1 | L12: 3.4 | M12: 1.7 | N12: 1.5 | O12: =L12+M12+N12 -> 6.6 | P12: =IF(O12=0,"",L12/O12) -> 0.51515152 | Q12: 30.935 | R12: =IF(AND(ISNUMBER(Q12),ISNUMBER(J12)),Q12/(J12/60),"") -> 3.0935 | S12: Zona 2EQ / Zona 3EQ
A13: Juvenil | B13: Control | C13: Juvenil – Control | D13: d-SLR (equilátero) | E13: Control oct 2025 | F13: Ranas | G13: 03/11/2025 | H13: 251103 D1 Ctrl-oct ranas | I13: 5 | J13: 600 | K13: Zona 1 | L13: 4.8 | M13: 5.5 | N13: 11.2 | O13: =L13+M13+N13 -> 21.5 | P13: =IF(O13=0,"",L13/O13) -> 0.22325581 | Q13: 31.469 | R13: =IF(AND(ISNUMBER(Q13),ISNUMBER(J13)),Q13/(J13/60),"") -> 3.1469 | S13: Zona 2EQ / Zona 3EQ
A14: Juvenil | B14: Control | C14: Juvenil – Control | D14: s-SLR (isósceles) | E14: Ctrl/Stevia jun 2025 | F14: — | G14: 05/06/2025 | H14: 250605 D1 Ctrl+Stevia | I14: con 5 | J14: 595.3 | K14: Zona 1 | L14: 18.8 | M14: 6.4 | N14: 12.4 | O14: =L14+M14+N14 -> 37.6 | P14: =IF(O14=0,"",L14/O14) -> 0.5 | Q14: 30.476 | R14: =IF(AND(ISNUMBER(Q14),ISNUMBER(J14)),Q14/(J14/60),"") -> 3.0716613 | S14: Zona 2 / Zona 3
A15: Juvenil | B15: Control | C15: Juvenil – Control | D15: s-SLR (isósceles) | E15: Ctrl/Stevia jun 2025 | F15: — | G15: 05/06/2025 | H15: 250605 D1 Ctrl+Stevia | I15: con 6 | J15: 598.5 | K15: Zona 1 | L15: 12.5 | M15: 12.7 | N15: 11.3 | O15: =L15+M15+N15 -> 36.5 | P15: =IF(O15=0,"",L15/O15) -> 0.34246575 | Q15: 32.772 | R15: =IF(AND(ISNUMBER(Q15),ISNUMBER(J15)),Q15/(J15/60),"") -> 3.2854135 | S15: Zona 2 / Zona 3
A16: Juvenil | B16: Control | C16: Juvenil – Control | D16: s-SLR (isósceles) | E16: Ctrl/Stevia jun 2025 | F16: — | G16: 05/06/2025 | H16: 250605 D1 Ctrl+Stevia | I16: con 7 | J16: 598.8 | K16: Zona 1 | L16: 5 | M16: 7.8 | N16: 10 | O16: =L16+M16+N16 -> 22.8 | P16: =IF(O16=0,"",L16/O16) -> 0.21929825 | Q16: 39.011 | R16: =IF(AND(ISNUMBER(Q16),ISNUMBER(J16)),Q16/(J16/60),"") -> 3.9089178 | S16: Zona 2 / Zona 3
A17: Juvenil | B17: Control | C17: Juvenil – Control | D17: s-SLR (isósceles) | E17: Ctrl/Stevia jun 2025 | F17: — | G17: 05/06/2025 | H17: 250605 D1 Ctrl+Stevia | I17: con 8 | J17: 598.4 | K17: Zona 1 | L17: 11.8 | M17: 9.7 | N17: 13.8 | O17: =L17+M17+N17 -> 35.3 | P17: =IF(O17=0,"",L17/O17) -> 0.33427762 | Q17: 35.066 | R17: =IF(AND(ISNUMBER(Q17),ISNUMBER(J17)),Q17/(J17/60),"") -> 3.5159759 | S17: Zona 2 / Zona 3
A18: Juvenil | B18: Control | C18: Juvenil – Control | D18: s-SLR (isósceles) | E18: Ctrl/Stevia jun 2025 | F18: — | G18: 05/06/2025 | H18: 250605 D1 Ctrl+Stevia | I18: con 9 | J18: 590.5 | K18: Zona 1 | L18: 6.9 | M18: 13.2 | N18: 8.8 | O18: =L18+M18+N18 -> 28.9 | P18: =IF(O18=0,"",L18/O18) -> 0.23875433 | Q18: 40.749 | R18: =IF(AND(ISNUMBER(Q18),ISNUMBER(J18)),Q18/(J18/60),"") -> 4.1404572 | S18: Zona 2 / Zona 3
A19: Juvenil | B19: Control | C19: Juvenil – Control | D19: s-SLR (isósceles) | E19: Control oct 2025 | F19: Vasos | G19: 30/10/2025 | H19: 251030 D1 Ctrl-oct vasos | I19: 4 | J19: sin dato | K19: Zona 1 | L19: 31 | M19: 9.9 | N19: 8.4 | O19: =L19+M19+N19 -> 49.3 | P19: =IF(O19=0,"",L19/O19) -> 0.62880325 | Q19: sin dato | R19: =IF(AND(ISNUMBER(Q19),ISNUMBER(J19)),Q19/(J19/60),"") | S19: Zona 2B / Zona 3B
A20: Juvenil | B20: Control | C20: Juvenil – Control | D20: s-SLR (isósceles) | E20: Control oct 2025 | F20: Vasos | G20: 30/10/2025 | H20: 251030 D1 Ctrl-oct vasos | I20: 5 | J20: sin dato | K20: Zona 1 | L20: 11 | M20: 9.4 | N20: 10.8 | O20: =L20+M20+N20 -> 31.2 | P20: =IF(O20=0,"",L20/O20) -> 0.3525641 | Q20: sin dato | R20: =IF(AND(ISNUMBER(Q20),ISNUMBER(J20)),Q20/(J20/60),"") | S20: Zona 2B / Zona 3B
A21: Juvenil | B21: Control | C21: Juvenil – Control | D21: s-SLR (isósceles) | E21: Control oct 2025 | F21: Ranas | G21: 03/11/2025 | H21: 251103 D1 Ctrl-oct ranas | I21: 1 | J21: 600 | K21: Zona 1 | L21: 10.1 | M21: 8.8 | N21: 7.1 | O21: =L21+M21+N21 -> 26 | P21: =IF(O21=0,"",L21/O21) -> 0.38846154 | Q21: 43.819 | R21: =IF(AND(ISNUMBER(Q21),ISNUMBER(J21)),Q21/(J21/60),"") -> 4.3819 | S21: Zona 2 / Zona 3
A22: Juvenil | B22: Control | C22: Juvenil – Control | D22: s-SLR (isósceles) | E22: Control oct 2025 | F22: Ranas | G22: 03/11/2025 | H22: 251103 D1 Ctrl-oct ranas | I22: 2 | J22: 600 | K22: Zona 1 | L22: 3.6 | M22: 13.6 | N22: 9.4 | O22: =L22+M22+N22 -> 26.6 | P22: =IF(O22=0,"",L22/O22) -> 0.13533835 | Q22: 29.204 | R22: =IF(AND(ISNUMBER(Q22),ISNUMBER(J22)),Q22/(J22/60),"") -> 2.9204 | S22: Zona 2 / Zona 3
A23: Juvenil | B23: Control | C23: Juvenil – Control | D23: s-SLR (isósceles) | E23: Control oct 2025 | F23: Ranas | G23: 03/11/2025 | H23: 251103 D1 Ctrl-oct ranas | I23: 3 | J23: 533.1 | K23: Zona 1 | L23: 1.9 | M23: 2.3 | N23: 7.6 | O23: =L23+M23+N23 -> 11.8 | P23: =IF(O23=0,"",L23/O23) -> 0.16101695 | Q23: 30.749 | R23: =IF(AND(ISNUMBER(Q23),ISNUMBER(J23)),Q23/(J23/60),"") -> 3.4607766 | S23: Zona 2 / Zona 3
A24: Juvenil | B24: Sacarosa | C24: Juvenil – Sacarosa | D24: d-SLR (equilátero) | E24: Sacarosa jun 2025 | F24: — | G24: 26/06/2025 | H24: 250626 D1 Sacarosa | I24: 1 | J24: 599.1 | K24: Zona 2 | L24: 12.2 | M24: 23.4 | N24: 12.1 | O24: =L24+M24+N24 -> 47.7 | P24: =IF(O24=0,"",L24/O24) -> 0.2557652 | Q24: 42.986 | R24: =IF(AND(ISNUMBER(Q24),ISNUMBER(J24)),Q24/(J24/60),"") -> 4.3050576 | S24: Zona 1 / Zona 3
A25: Juvenil | B25: Sacarosa | C25: Juvenil – Sacarosa | D25: d-SLR (equilátero) | E25: Sacarosa jun 2025 | F25: — | G25: 26/06/2025 | H25: 250626 D1 Sacarosa | I25: 2 | J25: 599.1 | K25: Zona 2 | L25: 33.6 | M25: 17.4 | N25: 26.6 | O25: =L25+M25+N25 -> 77.6 | P25: =IF(O25=0,"",L25/O25) -> 0.43298969 | Q25: 32.165 | R25: =IF(AND(ISNUMBER(Q25),ISNUMBER(J25)),Q25/(J25/60),"") -> 3.221332 | S25: Zona 1 / Zona 3
A26: Juvenil | B26: Sacarosa | C26: Juvenil – Sacarosa | D26: d-SLR (equilátero) | E26: Sacarosa jun 2025 | F26: — | G26: 26/06/2025 | H26: 250626 D1 Sacarosa | I26: 3 | J26: 597.5 | K26: Zona 2 | L26: 27.4 | M26: 16.2 | N26: 26.5 | O26: =L26+M26+N26 -> 70.1 | P26: =IF(O26=0,"",L26/O26) -> 0.39087019 | Q26: 48.313 | R26: =IF(AND(ISNUMBER(Q26),ISNUMBER(J26)),Q26/(J26/60),"") -> 4.8515146 | S26: Zona 1 / Zona 3
A27: Juvenil | B27: Sacarosa | C27: Juvenil – Sacarosa | D27: d-SLR (equilátero) | E27: Sacarosa jun 2025 | F27: — | G27: 26/06/2025 | H27: 250626 D1 Sacarosa | I27: 4 | J27: 597.7 | K27: Zona 2 | L27: 16.8 | M27: 11.8 | N27: 11.1 | O27: =L27+M27+N27 -> 39.7 | P27: =IF(O27=0,"",L27/O27) -> 0.4231738 | Q27: 39.034 | R27: =IF(AND(ISNUMBER(Q27),ISNUMBER(J27)),Q27/(J27/60),"") -> 3.9184206 | S27: Zona 1 / Zona 3
A28: Juvenil | B28: Sacarosa | C28: Juvenil – Sacarosa | D28: d-SLR (equilátero) | E28: Sac/Stevia 2026 par 1 | F28: Vasos | G28: 19/07/2026 | H28: 260719 D1 Par1 vasos | I28: JUV SAC 1 | J28: 594.1 | K28: ZONA 1 | L28: 19.5 | M28: 18.2 | N28: 13.9 | O28: =L28+M28+N28 -> 51.6 | P28: =IF(O28=0,"",L28/O28) -> 0.37790698 | Q28: 58.422 | R28: =IF(AND(ISNUMBER(Q28),ISNUMBER(J28)),Q28/(J28/60),"") -> 5.9002188 | S28: ZONA 2 / ZONA 3
A29: Juvenil | B29: Sacarosa | C29: Juvenil – Sacarosa | D29: d-SLR (equilátero) | E29: Sac/Stevia 2026 par 1 | F29: Vasos | G29: 19/07/2026 | H29: 260719 D1 Par1 vasos | I29: JUV SAC 2 | J29: 600 | K29: ZONA 1 | L29: 21.5 | M29: 24.5 | N29: 14.5 | O29: =L29+M29+N29 -> 60.5 | P29: =IF(O29=0,"",L29/O29) -> 0.3553719 | Q29: 47.865 | R29: =IF(AND(ISNUMBER(Q29),ISNUMBER(J29)),Q29/(J29/60),"") -> 4.7865 | S29: ZONA 2 / ZONA 3
A30: Juvenil | B30: Sacarosa | C30: Juvenil – Sacarosa | D30: d-SLR (equilátero) | E30: Sac/Stevia 2026 par 1 | F30: Vasos | G30: 19/07/2026 | H30: 260719 D1 Par1 vasos | I30: JUV SAC 3 | J30: 600 | K30: ZONA 1 | L30: 15.3 | M30: 22.1 | N30: 19.5 | O30: =L30+M30+N30 -> 56.9 | P30: =IF(O30=0,"",L30/O30) -> 0.26889279 | Q30: 63.973 | R30: =IF(AND(ISNUMBER(Q30),ISNUMBER(J30)),Q30/(J30/60),"") -> 6.3973 | S30: ZONA 2 / ZONA 3
A31: Juvenil | B31: Sacarosa | C31: Juvenil – Sacarosa | D31: d-SLR (equilátero) | E31: Sac/Stevia 2026 par 2 | F31: Ranas | G31: 23/07/2026 | H31: 260723 D1 Par2 ranas | I31: sac 4 | J31: 600 | K31: Zona 3 | L31: 12.6 | M31: 8.3 | N31: 10 | O31: =L31+M31+N31 -> 30.9 | P31: =IF(O31=0,"",L31/O31) -> 0.40776699 | Q31: 75.029 | R31: =IF(AND(ISNUMBER(Q31),ISNUMBER(J31)),Q31/(J31/60),"") -> 7.5029 | S31: Zona 2 / Zona 1
A32: Juvenil | B32: Sacarosa | C32: Juvenil – Sacarosa | D32: d-SLR (equilátero) | E32: Sac/Stevia 2026 par 2 | F32: Ranas | G32: 23/07/2026 | H32: 260723 D1 Par2 ranas | I32: sac 5 | J32: 600 | K32: Zona 3 | L32: 2 | M32: 4.3 | N32: 15.2 | O32: =L32+M32+N32 -> 21.5 | P32: =IF(O32=0,"",L32/O32) -> 0.093023256 | Q32: 60.576 | R32: =IF(AND(ISNUMBER(Q32),ISNUMBER(J32)),Q32/(J32/60),"") -> 6.0576 | S32: Zona 2 / Zona 1
... A61: Juvenil | B61: Stevia | C61: Juvenil – Stevia | D61: s-SLR (isósceles) | E61: Sac/Stevia 2026 par 1 | F61: Vasos | G61: 19/07/2026 | H61: 260719 D1 Par1 vasos | I61: JUV STEV 5 | J61: 600 | K61: ZONA 1 | L61: 31.5 | M61: 25.1 | N61: 26.6 | O61: =L61+M61+N61 -> 83.2 | P61: =IF(O61=0,"",L61/O61) -> 0.37860577 | Q61: 50.722 | R61: =IF(AND(ISNUMBER(Q61),ISNUMBER(J61)),Q61/(J61/60),"") -> 5.0722 | S61: ZONA 2 / ZONA 3
A62: Adulto | B62: Control | C62: Adulto – Control | D62: d-SLR (equilátero) | E62: Ctrl/Sac mayo 2025 | F62: — | G62: 08/05/2025 | H62: 250508 D1 CtrlSac equil | I62: con 1 | J62: 600 | K62: ZONA 2 | L62: 6.7 | M62: 10.4 | N62: 7.4 | O62: =L62+M62+N62 -> 24.5 | P62: =IF(O62=0,"",L62/O62) -> 0.27346939 | Q62: sin dato | R62: =IF(AND(ISNUMBER(Q62),ISNUMBER(J62)),Q62/(J62/60),"") | S62: ZONA 1 / ZONA 3
A63: Adulto | B63: Control | C63: Adulto – Control | D63: d-SLR (equilátero) | E63: Ctrl/Sac mayo 2025 | F63: — | G63: 08/05/2025 | H63: 250508 D1 CtrlSac equil | I63: con 2 | J63: 600 | K63: ZONA 2 | L63: 26 | M63: 9.5 | N63: 8.8 | O63: =L63+M63+N63 -> 44.3 | P63: =IF(O63=0,"",L63/O63) -> 0.58690745 | Q63: 28.981 | R63: =IF(AND(ISNUMBER(Q63),ISNUMBER(J63)),Q63/(J63/60),"") -> 2.8981 | S63: ZONA 1 / ZONA 3
A64: Adulto | B64: Control | C64: Adulto – Control | D64: d-SLR (equilátero) | E64: Ctrl/Sac mayo 2025 | F64: — | G64: 08/05/2025 | H64: 250508 D1 CtrlSac equil | I64: con 3 | J64: 600 | K64: ZONA 2 | L64: 31.1 | M64: 14.9 | N64: 13.8 | O64: =L64+M64+N64 -> 59.8 | P64: =IF(O64=0,"",L64/O64) -> 0.52006689 | Q64: 25.325 | R64: =IF(AND(ISNUMBER(Q64),ISNUMBER(J64)),Q64/(J64/60),"") -> 2.5325 | S64: ZONA 1 / ZONA 3
A65: Adulto | B65: Control | C65: Adulto – Control | D65: d-SLR (equilátero) | E65: Ctrl/Sac mayo 2025 | F65: — | G65: 08/05/2025 | H65: 250508 D1 CtrlSac equil | I65: con 4 | J65: 402 | K65: ZONA 2 | L65: 19.1 | M65: 26.4 | N65: 22.4 | O65: =L65+M65+N65 -> 67.9 | P65: =IF(O65=0,"",L65/O65) -> 0.28129602 | Q65: 28.246 | R65: =IF(AND(ISNUMBER(Q65),ISNUMBER(J65)),Q65/(J65/60),"") -> 4.2158209 | S65: ZONA 1 / ZONA 3
A66: Adulto | B66: Control | C66: Adulto – Control | D66: d-SLR (equilátero) | E66: Ctrl/Sac mayo 2025 | F66: — | G66: 08/05/2025 | H66: 250508 D1 CtrlSac equil | I66: con 5 | J66: 600 | K66: ZONA 2 | L66: 21.7 | M66: 14.4 | N66: 36 | O66: =L66+M66+N66 -> 72.1 | P66: =IF(O66=0,"",L66/O66) -> 0.30097087 | Q66: 27.796 | R66: =IF(AND(ISNUMBER(Q66),ISNUMBER(J66)),Q66/(J66/60),"") -> 2.7796 | S66: ZONA 1 / ZONA 3
A67: Adulto | B67: Control | C67: Adulto – Control | D67: d-SLR (equilátero) | E67: Control dic 2025 | F67: Vasos | G67: 18/12/2025 | H67: 251218 D1 Ctrl-dic vasos | I67: 1 | J67: 600 | K67: Zona 3 | L67: 12.7 | M67: 18.3 | N67: 7 | O67: =L67+M67+N67 -> 38 | P67: =IF(O67=0,"",L67/O67) -> 0.33421053 | Q67: 34.189 | R67: =IF(AND(ISNUMBER(Q67),ISNUMBER(J67)),Q67/(J67/60),"") -> 3.4189 | S67: Zona 1 / Zona 2
A68: Adulto | B68: Control | C68: Adulto – Control | D68: d-SLR (equilátero) | E68: Control dic 2025 | F68: Vasos | G68: 18/12/2025 | H68: 251218 D1 Ctrl-dic vasos | I68: 2 | J68: 600 | K68: Zona 3 | L68: 29.9 | M68: 15.1 | N68: 9.3 | O68: =L68+M68+N68 -> 54.3 | P68: =IF(O68=0,"",L68/O68) -> 0.55064457 | Q68: 33.276 | R68: =IF(AND(ISNUMBER(Q68),ISNUMBER(J68)),Q68/(J68/60),"") -> 3.3276 | S68: Zona 1 / Zona 2
A69: Adulto | B69: Control | C69: Adulto – Control | D69: d-SLR (equilátero) | E69: Control dic 2025 | F69: Vasos | G69: 18/12/2025 | H69: 251218 D1 Ctrl-dic vasos | I69: 3 | J69: 600 | K69: Zona 3 | L69: 7.6 | M69: 7 | N69: 11.3 | O69: =L69+M69+N69 -> 25.9 | P69: =IF(O69=0,"",L69/O69) -> 0.29343629 | Q69: 32.579 | R69: =IF(AND(ISNUMBER(Q69),ISNUMBER(J69)),Q69/(J69/60),"") -> 3.2579 | S69: Zona 1 / Zona 2
...

Sheet Prism
A1: Valores individuales del día 1 por grupo (columnas), listos para copiar a Prism
A2: Cada celda está vinculada a "Datos por animal". Seis bloques: exploración total, % en objeto fijo y distancia recorrida, en d-SLR y en s-SLR. Celdas vacías = sin dato.
A4: Exploración total D1 (s) – d-SLR (equilátero)
A5: Juvenil – Control | B5: Juvenil – Sacarosa | C5: Juvenil – Stevia | D5: Adulto – Control | E5: Adulto – Sacarosa | F5: Adulto – Stevia
A6: =IF(ISNUMBER('Datos por animal'!O5),'Datos por animal'!O5,"") -> 45.6 | B6: =IF(ISNUMBER('Datos por animal'!O24),'Datos por animal'!O24,"") -> 47.7 | C6: =IF(ISNUMBER('Datos por animal'!O42),'Datos por animal'!O42,"") -> 22.8 | D6: =IF(ISNUMBER('Datos por animal'!O62),'Datos por animal'!O62,"") -> 24.5 | E6: =IF(ISNUMBER('Datos por animal'!O82),'Datos por animal'!O82,"") -> 42.6 | F6: =IF(ISNUMBER('Datos por animal'!O102),'Datos por animal'!O102,"") -> 81.1
A7: =IF(ISNUMBER('Datos por animal'!O6),'Datos por animal'!O6,"") -> 54.3 | B7: =IF(ISNUMBER('Datos por animal'!O25),'Datos por animal'!O25,"") -> 77.6 | C7: =IF(ISNUMBER('Datos por animal'!O43),'Datos por animal'!O43,"") -> 19 | D7: =IF(ISNUMBER('Datos por animal'!O63),'Datos por animal'!O63,"") -> 44.3 | E7: =IF(ISNUMBER('Datos por animal'!O83),'Datos por animal'!O83,"") -> 29 | F7: =IF(ISNUMBER('Datos por animal'!O103),'Datos por animal'!O103,"") -> 49.7
A8: =IF(ISNUMBER('Datos por animal'!O7),'Datos por animal'!O7,"") -> 26.9 | B8: =IF(ISNUMBER('Datos por animal'!O26),'Datos por animal'!O26,"") -> 70.1 | C8: =IF(ISNUMBER('Datos por animal'!O44),'Datos por animal'!O44,"") -> 24.4 | D8: =IF(ISNUMBER('Datos por animal'!O64),'Datos por animal'!O64,"") -> 59.8 | E8: =IF(ISNUMBER('Datos por animal'!O84),'Datos por animal'!O84,"") -> 42.2 | F8: =IF(ISNUMBER('Datos por animal'!O104),'Datos por animal'!O104,"") -> 101.3
A9: =IF(ISNUMBER('Datos por animal'!O8),'Datos por animal'!O8,"") -> 25.3 | B9: =IF(ISNUMBER('Datos por animal'!O27),'Datos por animal'!O27,"") -> 39.7 | C9: =IF(ISNUMBER('Datos por animal'!O45),'Datos por animal'!O45,"") -> 34.9 | D9: =IF(ISNUMBER('Datos por animal'!O65),'Datos por animal'!O65,"") -> 67.9 | E9: =IF(ISNUMBER('Datos por animal'!O85),'Datos por animal'!O85,"") -> 24.3 | F9: =IF(ISNUMBER('Datos por animal'!O105),'Datos por animal'!O105,"") -> 57.2
A10: =IF(ISNUMBER('Datos por animal'!O9),'Datos por animal'!O9,"") -> 33.8 | B10: =IF(ISNUMBER('Datos por animal'!O28),'Datos por animal'!O28,"") -> 51.6 | C10: =IF(ISNUMBER('Datos por animal'!O46),'Datos por animal'!O46,"") -> 29.5 | D10: =IF(ISNUMBER('Datos por animal'!O66),'Datos por animal'!O66,"") -> 72.1 | E10: =IF(ISNUMBER('Datos por animal'!O86),'Datos por animal'!O86,"") -> 38.3 | F10: =IF(ISNUMBER('Datos por animal'!O106),'Datos por animal'!O106,"") -> 60.3
A11: =IF(ISNUMBER('Datos por animal'!O10),'Datos por animal'!O10,"") -> 30.6 | B11: =IF(ISNUMBER('Datos por animal'!O29),'Datos por animal'!O29,"") -> 60.5 | C11: =IF(ISNUMBER('Datos por animal'!O47),'Datos por animal'!O47,"") -> 70 | D11: =IF(ISNUMBER('Datos por animal'!O67),'Datos por animal'!O67,"") -> 38 | E11: =IF(ISNUMBER('Datos por animal'!O87),'Datos por animal'!O87,"") -> 26.9 | F11: =IF(ISNUMBER('Datos por animal'!O107),'Datos por animal'!O107,"") -> 30.3
A12: =IF(ISNUMBER('Datos por animal'!O11),'Datos por animal'!O11,"") -> 31.1 | B12: =IF(ISNUMBER('Datos por animal'!O30),'Datos por animal'!O30,"") -> 56.9 | C12: =IF(ISNUMBER('Datos por animal'!O48),'Datos por animal'!O48,"") -> 73.4 | D12: =IF(ISNUMBER('Datos por animal'!O68),'Datos por animal'!O68,"") -> 54.3 | E12: =IF(ISNUMBER('Datos por animal'!O88),'Datos por animal'!O88,"") -> 38 | F12: =IF(ISNUMBER('Datos por animal'!O108),'Datos por animal'!O108,"") -> 34.8
A13: =IF(ISNUMBER('Datos por animal'!O12),'Datos por animal'!O12,"") -> 6.6 | B13: =IF(ISNUMBER('Datos por animal'!O31),'Datos por animal'!O31,"") -> 30.9 | C13: =IF(ISNUMBER('Datos por animal'!O49),'Datos por animal'!O49,"") -> 96.4 | D13: =IF(ISNUMBER('Datos por animal'!O69),'Datos por animal'!O69,"") -> 25.9 | E13: =IF(ISNUMBER('Datos por animal'!O89),'Datos por animal'!O89,"") -> 35.5 | F13: =IF(ISNUMBER('Datos por animal'!O109),'Datos por animal'!O109,"") -> 35.4
A14: =IF(ISNUMBER('Datos por animal'!O13),'Datos por animal'!O13,"") -> 21.5 | B14: =IF(ISNUMBER('Datos por animal'!O32),'Datos por animal'!O32,"") -> 21.5 | C14: =IF(ISNUMBER('Datos por animal'!O50),'Datos por animal'!O50,"") -> 26.9 | D14: =IF(ISNUMBER('Datos por animal'!O70),'Datos por animal'!O70,"") -> 23.9 | E14: =IF(ISNUMBER('Datos por animal'!O90),'Datos por animal'!O90,"") -> 55.9 | F14: =IF(ISNUMBER('Datos por animal'!O110),'Datos por animal'!O110,"") -> 26.2
C15: =IF(ISNUMBER('Datos por animal'!O51),'Datos por animal'!O51,"") -> 37 | D15: =IF(ISNUMBER('Datos por animal'!O71),'Datos por animal'!O71,"") -> 18.1 | E15: =IF(ISNUMBER('Datos por animal'!O91),'Datos por animal'!O91,"") -> 39.1 | F15: =IF(ISNUMBER('Datos por animal'!O111),'Datos por animal'!O111,"") -> 84.4
A18: Exploración total D1 (s) – s-SLR (isósceles)
A19: Juvenil – Control | B19: Juvenil – Sacarosa | C19: Juvenil – Stevia | D19: Adulto – Control | E19: Adulto – Sacarosa | F19: Adulto – Stevia
A20: =IF(ISNUMBER('Datos por animal'!O14),'Datos por animal'!O14,"") -> 37.6 | B20: =IF(ISNUMBER('Datos por animal'!O33),'Datos por animal'!O33,"") -> 71.2 | C20: =IF(ISNUMBER('Datos por animal'!O52),'Datos por animal'!O52,"") -> 28.3 | D20: =IF(ISNUMBER('Datos por animal'!O72),'Datos por animal'!O72,"") -> 37.9 | E20: =IF(ISNUMBER('Datos por animal'!O92),'Datos por animal'!O92,"") -> 34.6 | F20: =IF(ISNUMBER('Datos por animal'!O112),'Datos por animal'!O112,"") -> 56.2
A21: =IF(ISNUMBER('Datos por animal'!O15),'Datos por animal'!O15,"") -> 36.5 | B21: =IF(ISNUMBER('Datos por animal'!O34),'Datos por animal'!O34,"") -> 43.1 | C21: =IF(ISNUMBER('Datos por animal'!O53),'Datos por animal'!O53,"") -> 50.2 | D21: =IF(ISNUMBER('Datos por animal'!O73),'Datos por animal'!O73,"") -> 44.4 | E21: =IF(ISNUMBER('Datos por animal'!O93),'Datos por animal'!O93,"") -> 27.1 | F21: =IF(ISNUMBER('Datos por animal'!O113),'Datos por animal'!O113,"") -> 74.8
A22: =IF(ISNUMBER('Datos por animal'!O16),'Datos por animal'!O16,"") -> 22.8 | B22: =IF(ISNUMBER('Datos por animal'!O35),'Datos por animal'!O35,"") -> 63.1 | C22: =IF(ISNUMBER('Datos por animal'!O54),'Datos por animal'!O54,"") -> 36.5 | D22: =IF(ISNUMBER('Datos por animal'!O74),'Datos por animal'!O74,"") -> 30.1 | E22: =IF(ISNUMBER('Datos por animal'!O94),'Datos por animal'!O94,"") -> 53 | F22: =IF(ISNUMBER('Datos por animal'!O114),'Datos por animal'!O114,"") -> 99.7
A23: =IF(ISNUMBER('Datos por animal'!O17),'Datos por animal'!O17,"") -> 35.3 | B23: =IF(ISNUMBER('Datos por animal'!O36),'Datos por animal'!O36,"") -> 59.4 | C23: =IF(ISNUMBER('Datos por animal'!O55),'Datos por animal'!O55,"") -> 28 | D23: =IF(ISNUMBER('Datos por animal'!O75),'Datos por animal'!O75,"") -> 26 | E23: =IF(ISNUMBER('Datos por animal'!O95),'Datos por animal'!O95,"") -> 34.8 | F23: =IF(ISNUMBER('Datos por animal'!O115),'Datos por animal'!O115,"") -> 79.1
A24: =IF(ISNUMBER('Datos por animal'!O18),'Datos por animal'!O18,"") -> 28.9 | B24: =IF(ISNUMBER('Datos por animal'!O37),'Datos por animal'!O37,"") -> 52.5 | C24: =IF(ISNUMBER('Datos por animal'!O56),'Datos por animal'!O56,"") -> 22.7 | D24: =IF(ISNUMBER('Datos por animal'!O76),'Datos por animal'!O76,"") -> 35.7 | E24: =IF(ISNUMBER('Datos por animal'!O96),'Datos por animal'!O96,"") -> 26.1 | F24: =IF(ISNUMBER('Datos por animal'!O116),'Datos por animal'!O116,"") -> 50.5
A25: =IF(ISNUMBER('Datos por animal'!O19),'Datos por animal'!O19,"") -> 49.3 | B25: =IF(ISNUMBER('Datos por animal'!O38),'Datos por animal'!O38,"") -> 43.5 | C25: =IF(ISNUMBER('Datos por animal'!O57),'Datos por animal'!O57,"") -> 16.4 | D25: =IF(ISNUMBER('Datos por animal'!O77),'Datos por animal'!O77,"") -> 17.9 | E25: =IF(ISNUMBER('Datos por animal'!O97),'Datos por animal'!O97,"") -> 33.5 | F25: =IF(ISNUMBER('Datos por animal'!O117),'Datos por animal'!O117,"") -> 29.6
A26: =IF(ISNUMBER('Datos por animal'!O20),'Datos por animal'!O20,"") -> 31.2 | B26: =IF(ISNUMBER('Datos por animal'!O39),'Datos por animal'!O39,"") -> 46.8 | C26: =IF(ISNUMBER('Datos por animal'!O58),'Datos por animal'!O58,"") -> 17.5 | D26: =IF(ISNUMBER('Datos por animal'!O78),'Datos por animal'!O78,"") -> 16.1 | E26: =IF(ISNUMBER('Datos por animal'!O98),'Datos por animal'!O98,"") -> 31.3 | F26: =IF(ISNUMBER('Datos por animal'!O118),'Datos por animal'!O118,"") -> 42.8
A27: =IF(ISNUMBER('Datos por animal'!O21),'Datos por animal'!O21,"") -> 26 | B27: =IF(ISNUMBER('Datos por animal'!O40),'Datos por animal'!O40,"") -> 74.5 | C27: =IF(ISNUMBER('Datos por animal'!O59),'Datos por animal'!O59,"") -> 64.4 | D27: =IF(ISNUMBER('Datos por animal'!O79),'Datos por animal'!O79,"") -> 20.9 | E27: =IF(ISNUMBER('Datos por animal'!O99),'Datos por animal'!O99,"") -> 50.8 | F27: =IF(ISNUMBER('Datos por animal'!O119),'Datos por animal'!O119,"") -> 24.7
A28: =IF(ISNUMBER('Datos por animal'!O22),'Datos por animal'!O22,"") -> 26.6 | B28: =IF(ISNUMBER('Datos por animal'!O41),'Datos por animal'!O41,"") -> 69.9 | C28: =IF(ISNUMBER('Datos por animal'!O60),'Datos por animal'!O60,"") -> 52.4 | D28: =IF(ISNUMBER('Datos por animal'!O80),'Datos por animal'!O80,"") -> 27.1 | E28: =IF(ISNUMBER('Datos por animal'!O100),'Datos por animal'!O100,"") -> 44.4 | F28: =IF(ISNUMBER('Datos por animal'!O120),'Datos por animal'!O120,"") -> 27.7
A29: =IF(ISNUMBER('Datos por animal'!O23),'Datos por animal'!O23,"") -> 11.8 | C29: =IF(ISNUMBER('Datos por animal'!O61),'Datos por animal'!O61,"") -> 83.2 | D29: =IF(ISNUMBER('Datos por animal'!O81),'Datos por animal'!O81,"") -> 49.3 | E29: =IF(ISNUMBER('Datos por animal'!O101),'Datos por animal'!O101,"") -> 42.1 | F29: =IF(ISNUMBER('Datos por animal'!O121),'Datos por animal'!O121,"") -> 69.3
A32: % tiempo en objeto fijo (azar 33,3 %) – d-SLR (equilátero)
A33: Juvenil – Control | B33: Juvenil – Sacarosa | C33: Juvenil – Stevia | D33: Adulto – Control | E33: Adulto – Sacarosa | F33: Adulto – Stevia
A34: =IF(ISNUMBER('Datos por animal'!P5),'Datos por animal'!P5,"") -> 0.18859649 | B34: =IF(ISNUMBER('Datos por animal'!P24),'Datos por animal'!P24,"") -> 0.2557652 | C34: =IF(ISNUMBER('Datos por animal'!P42),'Datos por animal'!P42,"") -> 0.22368421 | D34: =IF(ISNUMBER('Datos por animal'!P62),'Datos por animal'!P62,"") -> 0.27346939 | E34: =IF(ISNUMBER('Datos por animal'!P82),'Datos por animal'!P82,"") -> 0.42253521 | F34: =IF(ISNUMBER('Datos por animal'!P102),'Datos por animal'!P102,"") -> 0.36128237
A35: =IF(ISNUMBER('Datos por animal'!P6),'Datos por animal'!P6,"") -> 0.19889503 | B35: =IF(ISNUMBER('Datos por animal'!P25),'Datos por animal'!P25,"") -> 0.43298969 | C35: =IF(ISNUMBER('Datos por animal'!P43),'Datos por animal'!P43,"") -> 0.38421053 | D35: =IF(ISNUMBER('Datos por animal'!P63),'Datos por animal'!P63,"") -> 0.58690745 | E35: =IF(ISNUMBER('Datos por animal'!P83),'Datos por animal'!P83,"") -> 0.20689655 | F35: =IF(ISNUMBER('Datos por animal'!P103),'Datos por animal'!P103,"") -> 0.26156942
A36: =IF(ISNUMBER('Datos por animal'!P7),'Datos por animal'!P7,"") -> 0.26765799 | B36: =IF(ISNUMBER('Datos por animal'!P26),'Datos por animal'!P26,"") -> 0.39087019 | C36: =IF(ISNUMBER('Datos por animal'!P44),'Datos por animal'!P44,"") -> 0.16803279 | D36: =IF(ISNUMBER('Datos por animal'!P64),'Datos por animal'!P64,"") -> 0.52006689 | E36: =IF(ISNUMBER('Datos por animal'!P84),'Datos por animal'!P84,"") -> 0.12322275 | F36: =IF(ISNUMBER('Datos por animal'!P104),'Datos por animal'!P104,"") -> 0.24975321
A37: =IF(ISNUMBER('Datos por animal'!P8),'Datos por animal'!P8,"") -> 0.50988142 | B37: =IF(ISNUMBER('Datos por animal'!P27),'Datos por animal'!P27,"") -> 0.4231738 | C37: =IF(ISNUMBER('Datos por animal'!P45),'Datos por animal'!P45,"") -> 0.38681948 | D37: =IF(ISNUMBER('Datos por animal'!P65),'Datos por animal'!P65,"") -> 0.28129602 | E37: =IF(ISNUMBER('Datos por animal'!P85),'Datos por animal'!P85,"") -> 0.49382716 | F37: =IF(ISNUMBER('Datos por animal'!P105),'Datos por animal'!P105,"") -> 0.44230769
A38: =IF(ISNUMBER('Datos por animal'!P9),'Datos por animal'!P9,"") -> 0.37869822 | B38: =IF(ISNUMBER('Datos por animal'!P28),'Datos por animal'!P28,"") -> 0.37790698 | C38: =IF(ISNUMBER('Datos por animal'!P46),'Datos por animal'!P46,"") -> 0.3559322 | D38: =IF(ISNUMBER('Datos por animal'!P66),'Datos por animal'!P66,"") -> 0.30097087 | E38: =IF(ISNUMBER('Datos por animal'!P86),'Datos por animal'!P86,"") -> 0.4073107 | F38: =IF(ISNUMBER('Datos por animal'!P106),'Datos por animal'!P106,"") -> 0.28855721
A39: =IF(ISNUMBER('Datos por animal'!P10),'Datos por animal'!P10,"") -> 0.15686275 | B39: =IF(ISNUMBER('Datos por animal'!P29),'Datos por animal'!P29,"") -> 0.3553719 | C39: =IF(ISNUMBER('Datos por animal'!P47),'Datos por animal'!P47,"") -> 0.28285714 | D39: =IF(ISNUMBER('Datos por animal'!P67),'Datos por animal'!P67,"") -> 0.33421053 | E39: =IF(ISNUMBER('Datos por animal'!P87),'Datos por animal'!P87,"") -> 0.40892193 | F39: =IF(ISNUMBER('Datos por animal'!P107),'Datos por animal'!P107,"") -> 0.41254125
A40: =IF(ISNUMBER('Datos por animal'!P11),'Datos por animal'!P11,"") -> 0.42765273 | B40: =IF(ISNUMBER('Datos por animal'!P30),'Datos por animal'!P30,"") -> 0.26889279 | C40: =IF(ISNUMBER('Datos por animal'!P48),'Datos por animal'!P48,"") -> 0.47411444 | D40: =IF(ISNUMBER('Datos por animal'!P68),'Datos por animal'!P68,"") -> 0.55064457 | E40: =IF(ISNUMBER('Datos por animal'!P88),'Datos por animal'!P88,"") -> 0.52368421 | F40: =IF(ISNUMBER('Datos por animal'!P108),'Datos por animal'!P108,"") -> 0.63505747
A41: =IF(ISNUMBER('Datos por animal'!P12),'Datos por animal'!P12,"") -> 0.51515152 | B41: =IF(ISNUMBER('Datos por animal'!P31),'Datos por animal'!P31,"") -> 0.40776699 | C41: =IF(ISNUMBER('Datos por animal'!P49),'Datos por animal'!P49,"") -> 0.45435685 | D41: =IF(ISNUMBER('Datos por animal'!P69),'Datos por animal'!P69,"") -> 0.29343629 | E41: =IF(ISNUMBER('Datos por animal'!P89),'Datos por animal'!P89,"") -> 0.23380282 | F41: =IF(ISNUMBER('Datos por animal'!P109),'Datos por animal'!P109,"") -> 0.44067797
A42: =IF(ISNUMBER('Datos por animal'!P13),'Datos por animal'!P13,"") -> 0.22325581 | B42: =IF(ISNUMBER('Datos por animal'!P32),'Datos por animal'!P32,"") -> 0.093023256 | C42: =IF(ISNUMBER('Datos por animal'!P50),'Datos por animal'!P50,"") -> 0.2936803 | D42: =IF(ISNUMBER('Datos por animal'!P70),'Datos por animal'!P70,"") -> 0.30125523 | E42: =IF(ISNUMBER('Datos por animal'!P90),'Datos por animal'!P90,"") -> 0.37030411 | F42: =IF(ISNUMBER('Datos por animal'!P110),'Datos por animal'!P110,"") -> 0.14885496
C43: =IF(ISNUMBER('Datos por animal'!P51),'Datos por animal'!P51,"") -> 0.39189189 | D43: =IF(ISNUMBER('Datos por animal'!P71),'Datos por animal'!P71,"") -> 0.22651934 | E43: =IF(ISNUMBER('Datos por animal'!P91),'Datos por animal'!P91,"") -> 0.48081841 | F43: =IF(ISNUMBER('Datos por animal'!P111),'Datos por animal'!P111,"") -> 0.1563981
A46: % tiempo en objeto fijo (azar 33,3 %) – s-SLR (isósceles)
A47: Juvenil – Control | B47: Juvenil – Sacarosa | C47: Juvenil – Stevia | D47: Adulto – Control | E47: Adulto – Sacarosa | F47: Adulto – Stevia
...
